Workbook

Sheet TP
A1: Season | B1: Team | C1: Possession | D1: Ranking
A2: 2022 | B2: San Antonio | C2: 43.42 | D2: 2.0136813
A3: 2022 | B3: Louisville City | C3: 54.54 | D3: 1.8195865
A4: 2022 | B4: Memphis 901 | C4: 50.62 | D4: 1.5252844
A5: 2022 | B5: San Diego Loyal | C5: 55.63 | D5: 1.2147328
A6: 2022 | B6: Tampa Bay Rowdies | C6: 52.39 | D6: 1.3474392
A7: 2022 | B7: Colorado Springs | C7: 52.16 | D7: 0.88161168
A8: 2022 | B8: Birmingham Legion | C8: 49.76 | D8: 0.85904225
A9: 2022 | B9: Sacramento Republic | C9: 48.87 | D9: 0.66494747
A10: 2022 | B10: Pittsburgh Riverhounds | C10: 50.52 | D10: 0.681197
A11: 2022 | B11: New Mexico United | C11: 50.1 | D11: 0.44828326
A12: 2022 | B12: Miami | C12: 49.1 | D12: 0.46453279
A13: 2022 | B13: Rio Grande Valley | C13: 51.78 | D13: 0.23161905
... A106: 2025 | B106: Ventura County | C106: 53.29 | D106: -0.069781153

Sheet GK
A1: Season | B1: 900+ mins | C1: Team | D1: Possession | E1: Total STDEV | F1: Overall Rank | H1: Short / medium passes per 90 | K1: Accurate short / medium passes, % | O1: Short / Medium Passsing Impact | Q1: Long passes per 90 | T1: Accurate long passes, % | X1: Long Passing Impact | Z1: Progressive passes per 90 | AC1: Accurate progressive passes, % | AG1: Progressive passing Impact | AH1: Passing Impact Stdev | AI1: Passing Impact Percentile | AK1: Conceded goals per 90 | AM1: Shots Against P90 | AQ1: Save rate, % | AU1: Save Impact | AW1: Prevented goals per 90 | AZ1: Aerial duels per 90 | BC1: Padj Aerial duels per 90 | BF1: Aerial duels won, % | BJ1: Padj Aerial duel Impact | BM1: Padj Exits per 90 | BO1: Goal Impact Stdev | BP1: Goal Impact Percentile
A2: 2024 | B2: C. Herrera | C2: Monterey Bay FC | D2: {=INDEX( TP!C:C, MATCH( 1, (TP!A:A = A2) * (TP!B:B = C2), 0 ) )} -> 49.08 | E2: =sum(AH2,BO2) -> 8.6328706 | F2: =PERCENTRANK(E$2:E$134,E2) -> 1 | G2: 20.56 | H2: =PERCENTRANK(G$2:G$134,G2) -> 0.917 | I2: =sum(G2-G$136)/G$137 -> 1.6168809 | J2: 98.04 | K2: =PERCENTRANK(J$2:J$134,J2) -> 0.614 | L2: =sum(J2-J$136)/J$137 -> 0.42999411 | M2: =(J2 * LOG(G2 + 1)) / LOG(MAX(G$2:G$134) + 1) * 100 -> 8792.9521 | N2: =sum(M2-M$136)/M$137 -> 1.5037235 | O2: =PERCENTRANK(N$2:N$134,N2) -> 0.917 | P2: 8.16 | Q2: =PERCENTRANK(P$2:P$134,P2) -> 0.75 | R2: =sum(P2-P$136)/P$137 -> 0.61058534 | S2: 64.2 | T2: =PERCENTRANK(S$2:S$134,S2) -> 0.705 | U2: =sum(S2-S$136)/S$137 -> 0.61666374 | V2: =(S2 * LOG(P2 + 1)) / LOG(MAX(P$2:P$134) + 1) * 100 -> 5197.7529 | W2: =sum(V2-V$136)/V$137 -> 0.89099749 | X2: =PERCENTRANK(W$2:W$134,W2) -> 0.833 | Y2: 5.85 | Z2: =PERCENTRANK(Y$2:Y$134,Y2) -> 0.78 | AA2: =sum(Y2-Y$136)/Y$137 -> 0.60863983 | AB2: 62.07 | AC2: =PERCENTRANK(AB$2:AB$134,AB2) -> 0.174 | AD2: =sum(AB2-AB$136)/AB$137 -> -0.87993805 | AE2: =(AB2 * LOG(Y2 + 1)) / LOG(MAX(Y$2:Y$134) + 1) * 100 -> 4844.271 | AF2: =sum(AE2-AE$136)/AE$137 -> -0.11409304 | AG2: =PERCENTRANK(AF$2:AF$134,AF2) -> 0.455 | AH2: =sum(AG2,X2,O2) -> 2.205 | AI2: =PERCENTRANK(AH$2:AH$134,AH2) -> 0.871 | AJ2: 0.91 | AK2: =PERCENTRANK(AJ$2:AJ$134,AJ2) -> 0.144 | AL2: =1-(AJ2-AJ$136)/AJ$137 -> 1.8909053 | AM2: 4.33 | AN2: =PERCENTRANK(AM$2:AM$134,AM2) -> 0.758 | AO2: =sum(AM2-AM$136)/AM$137 -> 0.45746083 | AP2: 79.07 | AQ2: =PERCENTRANK(AP$2:AP$134,AP2) -> 0.985 | AR2: =sum(AP2-AP$136)/AP$137 -> 1.8427963 | AS2: =(AP2 * LOG(AM2 + 1)) / LOG(MAX(AM$2:AM$134) + 1) * 100 -> 6295.493 | AT2: =sum(AS2-AS$136)/AS$137 -> 1.6885166 | AU2: =PERCENTRANK(AT$2:AT$134,AT2) -> 0.962 | AV2: 0.089 | AW2: =PERCENTRANK(AV$2:AV$134,AV2) -> 0.811 | AX2: =sum(AV2-AV$136)/AV$137 -> 0.8439291 | AY2: 1.01 | AZ2: =PERCENTRANK(AY$2:AY$134,AY2) -> 0.985 | BA2: =sum(AY2-AY$136)/AY$137 -> 2.3442152 | BB2: =AY2 * (2/(1+EXP(-7*(($D2/100)-0.5)))) -> 0.97748924 | BC2: =PERCENTRANK(BB$2:BB$134,BB2) -> 0.97 | BD2: =sum(BB2-BB$136)/BB$137 -> 2.1800795 | BE2: 100 | BF2: =PERCENTRANK(BE$2:BE$134,BE2) -> 0.697 | BG2: =sum(BE2-BE$136)/BE$137 -> 0.72023098 | BH2: =(BE2 * LOG(BB2 + 1)) / LOG(MAX(BB$2:BB$134) + 1) * 100 -> 7510.5707 | BI2: =sum(BH2-BH$136)/BH$137 -> 2.4193383 | BJ2: =PERCENTRANK(BI$2:BI$134,BI2) -> 0.992 | BK2: 2.12 | BL2: =BK2 * (2/(1+EXP(-7*(($D2/100)-0.5)))) -> 2.0517596 | BM2: =PERCENTRANK(BL$2:BL$134,BL2) -> 0.902 | BN2: =sum(BL2-BL$136)/BK$137 -> 1.2736978 | BO2: =sum(AL2,AX2,BI2,BN2) -> 6.4278706 | BP2: =PERCENTRANK(BO$2:BO$134,BO2) -> 0.992
A3: 2024 | B3: K. Ndiaye | C3: Miami | D3: {=INDEX( TP!C:C, MATCH( 1, (TP!A:A = A3) * (TP!B:B = C3), 0 ) )} -> 44.7 | E3: =sum(AH3,BO3) -> 6.2154387 | F3: =PERCENTRANK(E$2:E$134,E3) -> 0.924 | G3: 12.12 | H3: =PERCENTRANK(G$2:G$134,G3) -> 0.508 | I3: =sum(G3-G$136)/G$137 -> -0.15764115 | J3: 92.62 | K3: =PERCENTRANK(J$2:J$134,J3) -> 0 | L3: =sum(J3-J$136)/J$137 -> -3.7564666 | M3: =(J3 * LOG(G3 + 1)) / LOG(MAX(G$2:G$134) + 1) * 100 -> 6963.2312 | N3: =sum(M3-M$136)/M$137 -> -0.38280391 | O3: =PERCENTRANK(N$2:N$134,N3) -> 0.273 | P3: 4.57 | Q3: =PERCENTRANK(P$2:P$134,P3) -> 0.076 | R3: =sum(P3-P$136)/P$137 -> -1.1567291 | S3: 41.3 | T3: =PERCENTRANK(S$2:S$134,S3) -> 0 | U3: =sum(S3-S$136)/S$137 -> -2.6497805 | V3: =(S3 * LOG(P3 + 1)) / LOG(MAX(P$2:P$134) + 1) * 100 -> 2592.73 | W3: =sum(V3-V$136)/V$137 -> -2.3068874 | X3: =PERCENTRANK(W$2:W$134,W3) -> 0 | Y3: 3.38 | Z3: =PERCENTRANK(Y$2:Y$134,Y3) -> 0.068 | AA3: =sum(Y3-Y$136)/Y$137 -> -1.1011624 | AB3: 52.94 | AC3: =PERCENTRANK(AB$2:AB$134,AB3) -> 0.023 | AD3: =sum(AB3-AB$136)/AB$137 -> -2.0249476 | AE3: =(AB3 * LOG(Y3 + 1)) / LOG(MAX(Y$2:Y$134) + 1) * 100 -> 3171.4966 | AF3: =sum(AE3-AE$136)/AE$137 -> -1.7994268 | AG3: =PERCENTRANK(AF$2:AF$134,AF3) -> 0.023 | AH3: =sum(AG3,X3,O3) -> 0.296 | AI3: =PERCENTRANK(AH$2:AH$134,AH3) -> 0.015 | AJ3: 1.79 | AK3: =PERCENTRANK(AJ$2:AJ$134,AJ3) -> 0.917 | AL3: =1-(AJ3-AJ$136)/AJ$137 -> -0.34620172 | AM3: 6.26 | AN3: =PERCENTRANK(AM$2:AM$134,AM3) -> 0.97 | AO3: =sum(AM3-AM$136)/AM$137 -> 2.5539726 | AP3: 71.43 | AQ3: =PERCENTRANK(AP$2:AP$134,AP3) -> 0.735 | AR3: =sum(AP3-AP$136)/AP$137 -> 0.59607393 | AS3: =(AP3 * LOG(AM3 + 1)) / LOG(MAX(AM$2:AM$134) + 1) * 100 -> 6737.4944 | AT3: =sum(AS3-AS$136)/AS$137 -> 2.3018486 | AU3: =PERCENTRANK(AT$2:AT$134,AT3) -> 0.985 | AV3: 0.272 | AW3: =PERCENTRANK(AV$2:AV$134,AV3) -> 0.985 | AX3: =sum(AV3-AV$136)/AV$137 -> 1.7951814 | AY3: 1.19 | AZ3: =PERCENTRANK(AY$2:AY$134,AY3) -> 0.992 | BA3: =sum(AY3-AY$136)/AY$137 -> 3.1106794 | BB3: =AY3 * (2/(1+EXP(-7*(($D3/100)-0.5)))) -> 0.97175259 | BC3: =PERCENTRANK(BB$2:BB$134,BB3) -> 0.962 | BD3: =sum(BB3-BB$136)/BB$137 -> 2.1560863 | BE3: 91.67 | BF3: =PERCENTRANK(BE$2:BE$134,BE3) -> 0.492 | BG3: =sum(BE3-BE$136)/BE$137 -> 0.22024558 | BH3: =(BE3 * LOG(BB3 + 1)) / LOG(MAX(BB$2:BB$134) + 1) * 100 -> 6855.6042 | BI3: =sum(BH3-BH$136)/BH$137 -> 2.0124442 | BJ3: =PERCENTRANK(BI$2:BI$134,BI3) -> 0.97 | BK3: 3.18 | BL3: =BK3 * (2/(1+EXP(-7*(($D3/100)-0.5)))) -> 2.5967842 | BM3: =PERCENTRANK(BL$2:BL$134,BL3) -> 0.992 | BN3: =sum(BL3-BL$136)/BK$137 -> 2.4580149 | BO3: =sum(AL3,AX3,BI3,BN3) -> 5.9194387 | BP3: =PERCENTRANK(BO$2:BO$134,BO3) -> 0.97
A4: 2022 | B4: P. Blanchette | C4: Oakland Roots | D4: {=INDEX( TP!C:C, MATCH( 1, (TP!A:A = A4) * (TP!B:B = C4), 0 ) )} -> 52.67 | E4: =sum(AH4,BO4) -> 8.5664409 | F4: =PERCENTRANK(E$2:E$134,E4) -> 0.992 | G4: 12.58 | H4: =PERCENTRANK(G$2:G$134,G4) -> 0.576 | I4: =sum(G4-G$136)/G$137 -> -0.06092549 | J4: 96.99 | K4: =PERCENTRANK(J$2:J$134,J4) -> 0.311 | L4: =sum(J4-J$136)/J$137 -> -0.38103611 | M4: =(J4 * LOG(G4 + 1)) / LOG(MAX(G$2:G$134) + 1) * 100 -> 7389.3866 | N4: =sum(M4-M$136)/M$137 -> 0.056582105 | O4: =PERCENTRANK(N$2:N$134,N4) -> 0.553 | P4: 10.64 | Q4: =PERCENTRANK(P$2:P$134,P4) -> 0.947 | R4: =sum(P4-P$136)/P$137 -> 1.8314599 | S4: 57.33 | T4: =PERCENTRANK(S$2:S$134,S4) -> 0.371 | U4: =sum(S4-S$136)/S$137 -> -0.36326952 | V4: =(S4 * LOG(P4 + 1)) / LOG(MAX(P$2:P$134) + 1) * 100 -> 5143.6654 | W4: =sum(V4-V$136)/V$137 -> 0.82460054 | X4: =PERCENTRANK(W$2:W$134,W4) -> 0.818 | Y4: 7.71 | Z4: =PERCENTRANK(Y$2:Y$134,Y4) -> 0.955 | AA4: =sum(Y4-Y$136)/Y$137 -> 1.8961832 | AB4: 64.42 | AC4: =PERCENTRANK(AB$2:AB$134,AB4) -> 0.242 | AD4: =sum(AB4-AB$136)/AB$137 -> -0.58522038 | AE4: =(AB4 * LOG(Y4 + 1)) / LOG(MAX(Y$2:Y$134) + 1) * 100 -> 5655.3325 | AF4: =sum(AE4-AE$136)/AE$137 -> 0.703058 | AG4: =PERCENTRANK(AF$2:AF$134,AF4) -> 0.773 | AH4: =sum(AG4,X4,O4) -> 2.144 | AI4: =PERCENTRANK(AH$2:AH$134,AH4) -> 0.833 | AJ4: 1.18 | AK4: =PERCENTRANK(AJ$2:AJ$134,AJ4) -> 0.477 | AL4: =1-(AJ4-AJ$136)/AJ$137 -> 1.2045202 | AM4: 4.68 | AN4: =PERCENTRANK(AM$2:AM$134,AM4) -> 0.856 | AO4: =sum(AM4-AM$136)/AM$137 -> 0.83765726 | AP4: 74.75 | AQ4: =PERCENTRANK(AP$2:AP$134,AP4) -> 0.894 | AR4: =sum(AP4-AP$136)/AP$137 -> 1.1378433 | AS4: =(AP4 * LOG(AM4 + 1)) / LOG(MAX(AM$2:AM$134) + 1) * 100 -> 6177.7413 | AT4: =sum(AS4-AS$136)/AS$137 -> 1.5251215 | AU4: =PERCENTRANK(AT$2:AT$134,AT4) -> 0.939 | AV4: 0.255 | AW4: =PERCENTRANK(AV$2:AV$134,AV4) -> 0.977 | AX4: =sum(AV4-AV$136)/AV$137 -> 1.7068137 | AY4: 0.71 | AZ4: =PERCENTRANK(AY$2:AY$134,AY4) -> 0.864 | BA4: =sum(AY4-AY$136)/AY$137 -> 1.0667748 | BB4: =AY4 * (2/(1+EXP(-7*(($D4/100)-0.5)))) -> 0.77615703 | BC4: =PERCENTRANK(BB$2:BB$134,BB4) -> 0.917 | BD4: =sum(BB4-BB$136)/BB$137 -> 1.3380192 | BE4: 93.33 | BF4: =PERCENTRANK(BE$2:BE$134,BE4) -> 0.598 | BG4: =sum(BE4-BE$136)/BE$137 -> 0.31988252 | BH4: =(BE4 * LOG(BB4 + 1)) / LOG(MAX(BB$2:BB$134) + 1) * 100 -> 5905.7244 | BI4: =sum(BH4-BH$136)/BH$137 -> 1.4223368 | BJ4: =PERCENTRANK(BI$2:BI$134,BI4) -> 0.924 | BK4: 2.22 | BL4: =BK4 * (2/(1+EXP(-7*(($D4/100)-0.5)))) -> 2.4268572 | BM4: =PERCENTRANK(BL$2:BL$134,BL4) -> 0.97 | BN4: =sum(BL4-BL$136)/BK$137 -> 2.0887701 | BO4: =sum(AL4,AX4,BI4,BN4) -> 6.4224409 | BP4: =PERCENTRANK(BO$2:BO$134,BO4) -> 0.985
A5: 2023 | B5: D. Vitiello | C5: Sacramento Republic | D5: {=INDEX( TP!C:C, MATCH( 1, (TP!A:A = A5) * (TP!B:B = C5), 0 ) )} -> 48.42 | E5: =sum(AH5,BO5) -> 7.1567537 | F5: =PERCENTRANK(E$2:E$134,E5) -> 0.962 | G5: 13.49 | H5: =PERCENTRANK(G$2:G$134,G5) -> 0.652 | I5: =sum(G5-G$136)/G$137 -> 0.13040331 | J5: 97.13 | K5: =PERCENTRANK(J$2:J$134,J5) -> 0.341 | L5: =sum(J5-J$136)/J$137 -> -0.27289875 | M5: =(J5 * LOG(G5 + 1)) / LOG(MAX(G$2:G$134) + 1) * 100 -> 7584.049 | N5: =sum(M5-M$136)/M$137 -> 0.25728809 | O5: =PERCENTRANK(N$2:N$134,N5) -> 0.629 | P5: 7.84 | Q5: =PERCENTRANK(P$2:P$134,P5) -> 0.712 | R5: =sum(P5-P$136)/P$137 -> 0.45305314 | S5: 61.48 | T5: =PERCENTRANK(S$2:S$134,S5) -> 0.568 | U5: =sum(S5-S$136)/S$137 -> 0.22868434 | V5: =(S5 * LOG(P5 + 1)) / LOG(MAX(P$2:P$134) + 1) * 100 -> 4897.6223 | W5: =sum(V5-V$136)/V$137 -> 0.52256198 | X5: =PERCENTRANK(W$2:W$134,W5) -> 0.758 | Y5: 5.98 | Z5: =PERCENTRANK(Y$2:Y$134,Y5) -> 0.803 | AA5: =sum(Y5-Y$136)/Y$137 -> 0.69862943 | AB5: 72.22 | AC5: =PERCENTRANK(AB$2:AB$134,AB5) -> 0.583 | AD5: =sum(AB5-AB$136)/AB$137 -> 0.39299147 | AE5: =(AB5 * LOG(Y5 + 1)) / LOG(MAX(Y$2:Y$134) + 1) * 100 -> 5691.4996 | AF5: =sum(AE5-AE$136)/AE$137 -> 0.73949668 | AG5: =PERCENTRANK(AF$2:AF$134,AF5) -> 0.803 | AH5: =sum(AG5,X5,O5) -> 2.19 | AI5: =PERCENTRANK(AH$2:AH$134,AH5) -> 0.864 | AJ5: 0.78 | AK5: =PERCENTRANK(AJ$2:AJ$134,AJ5) -> 0.068 | AL5: =1-(AJ5-AJ$136)/AJ$137 -> 2.2213871 | AM5: 3.21 | AN5: =PERCENTRANK(AM$2:AM$134,AM5) -> 0.212 | AO5: =sum(AM5-AM$136)/AM$137 -> -0.75916773 | AP5: 75.86 | AQ5: =PERCENTRANK(AP$2:AP$134,AP5) -> 0.917 | AR5: =sum(AP5-AP$136)/AP$137 -> 1.3189771 | AS5: =(AP5 * LOG(AM5 + 1)) / LOG(MAX(AM$2:AM$134) + 1) * 100 -> 5188.4819 | AT5: =sum(AS5-AS$136)/AS$137 -> 0.15240072 | AU5: =PERCENTRANK(AT$2:AT$134,AT5) -> 0.576 | AV5: 0.032 | AW5: =PERCENTRANK(AV$2:AV$134,AV5) -> 0.682 | AX5: =sum(AV5-AV$136)/AV$137 -> 0.54763741 | AY5: 0.69 | AZ5: =PERCENTRANK(AY$2:AY$134,AY5) -> 0.848 | BA5: =sum(AY5-AY$136)/AY$137 -> 0.9816121 | BB5: =AY5 * (2/(1+EXP(-7*(($D5/100)-0.5)))) -> 0.65188185 | BC5: =PERCENTRANK(BB$2:BB$134,BB5) -> 0.841 | BD5: =sum(BB5-BB$136)/BB$137 -> 0.81824553 | BE5: 96 | BF5: =PERCENTRANK(BE$2:BE$134,BE5) -> 0.682 | BG5: =sum(BE5-BE$136)/BE$137 -> 0.48014195 | BH5: =(BE5 * LOG(BB5 + 1)) / LOG(MAX(BB$2:BB$134) + 1) * 100 -> 5307.618 | BI5: =sum(BH5-BH$136)/BH$137 -> 1.0507667 | BJ5: =PERCENTRANK(BI$2:BI$134,BI5) -> 0.871 | BK5: 2.11 | BL5: =BK5 * (2/(1+EXP(-7*(($D5/100)-0.5)))) -> 1.9934358 | BM5: =PERCENTRANK(BL$2:BL$134,BL5) -> 0.894 | BN5: =sum(BL5-BL$136)/BK$137 -> 1.1469625 | BO5: =sum(AL5,AX5,BI5,BN5) -> 4.9667537 | BP5: =PERCENTRANK(BO$2:BO$134,BO5) -> 0.947
A6: 2024 | B6: Renan Ribeiro | C6: Hartford Athletic | D6: {=INDEX( TP!C:C, MATCH( 1, (TP!A:A = A6) * (TP!B:B = C6), 0 ) )} -> 48.96 | E6: =sum(AH6,BO6) -> 7.0120131 | F6: =PERCENTRANK(E$2:E$134,E6) -> 0.955 | G6: 14.13 | H6: =PERCENTRANK(G$2:G$134,G6) -> 0.705 | I6: =sum(G6-G$136)/G$137 -> 0.26496423 | J6: 97.81 | K6: =PERCENTRANK(J$2:J$134,J6) -> 0.515 | L6: =sum(J6-J$136)/J$137 -> 0.25233987 | M6: =(J6 * LOG(G6 + 1)) / LOG(MAX(G$2:G$134) + 1) * 100 -> 7760.6111 | N6: =sum(M6-M$136)/M$137 -> 0.43933186 | O6: =PERCENTRANK(N$2:N$134,N6) -> 0.705 | P6: 8.53 | Q6: =PERCENTRANK(P$2:P$134,P6) -> 0.803 | R6: =sum(P6-P$136)/P$137 -> 0.79273195 | S6: 61.29 | T6: =PERCENTRANK(S$2:S$134,S6) -> 0.553 | U6: =sum(S6-S$136)/S$137 -> 0.20158284 | V6: =(S6 * LOG(P6 + 1)) / LOG(MAX(P$2:P$134) + 1) * 100 -> 5050.8706 | W6: =sum(V6-V$136)/V$137 -> 0.71068712 | X6: =PERCENTRANK(W$2:W$134,W6) -> 0.78 | Y6: 4.81 | Z6: =PERCENTRANK(Y$2:Y$134,Y6) -> 0.515 | AA6: =sum(Y6-Y$136)/Y$137 -> -0.11127689 | AB6: 80.71 | AC6: =PERCENTRANK(AB$2:AB$134,AB6) -> 0.939 | AD6: =sum(AB6-AB$136)/AB$137 -> 1.4577375 | AE6: =(AB6 * LOG(Y6 + 1)) / LOG(MAX(Y$2:Y$134) + 1) * 100 -> 5759.9936 | AF6: =sum(AE6-AE$136)/AE$137 -> 0.80850488 | AG6: =PERCENTRANK(AF$2:AF$134,AF6) -> 0.811 | AH6: =sum(AG6,X6,O6) -> 2.296 | AI6: =PERCENTRANK(AH$2:AH$134,AH6) -> 0.902 | AJ6: 1.1 | AK6: =PERCENTRANK(AJ$2:AJ$134,AJ6) -> 0.371 | AL6: =1-(AJ6-AJ$136)/AJ$137 -> 1.4078936 | AM6: 4.61 | AN6: =PERCENTRANK(AM$2:AM$134,AM6) -> 0.841 | AO6: =sum(AM6-AM$136)/AM$137 -> 0.76161798 | AP6: 76.12 | AQ6: =PERCENTRANK(AP$2:AP$134,AP6) -> 0.924 | AR6: =sum(AP6-AP$136)/AP$137 -> 1.3614048 | AS6: =(AP6 * LOG(AM6 + 1)) / LOG(MAX(AM$2:AM$134) + 1) * 100 -> 6246.0528 | AT6: =sum(AS6-AS$136)/AS$137 -> 1.6199121 | AU6: =PERCENTRANK(AT$2:AT$134,AT6) -> 0.955 | AV6: 0.24 | AW6: =PERCENTRANK(AV$2:AV$134,AV6) -> 0.97 | AX6: =sum(AV6-AV$136)/AV$137 -> 1.6288422 | AY6: 0.65 | AZ6: =PERCENTRANK(AY$2:AY$134,AY6) -> 0.795 | BA6: =sum(AY6-AY$136)/AY$137 -> 0.81128671 | BB6: =AY6 * (2/(1+EXP(-7*(($D6/100)-0.5)))) -> 0.62635044 | BC6: =PERCENTRANK(BB$2:BB$134,BB6) -> 0.811 | BD6: =sum(BB6-BB$136)/BB$137 -> 0.71146192 | BE6: 94.74 | BF6: =PERCENTRANK(BE$2:BE$134,BE6) -> 0.674 | BG6: =sum(BE6-BE$136)/BE$137 -> 0.40451391 | BH6: =(BE6 * LOG(BB6 + 1)) / LOG(MAX(BB$2:BB$134) + 1) * 100 -> 5075.3987 | BI6: =sum(BH6-BH$136)/BH$137 -> 0.90650176 | BJ6: =PERCENTRANK(BI$2:BI$134,BI6) -> 0.841 | BK6: 1.89 | BL6: =BK6 * (2/(1+EXP(-7*(($D6/100)-0.5)))) -> 1.8212344 | BM6: =PERCENTRANK(BL$2:BL$134,BL6) -> 0.773 | BN6: =sum(BL6-BL$136)/BK$137 -> 0.77277563 | BO6: =sum(AL6,AX6,BI6,BN6) -> 4.7160131 | BP6: =PERCENTRANK(BO$2:BO$134,BO6) -> 0.932
A7: 2025 | B7: E. Dick | C7: Pittsburgh Riverhounds | D7: {=INDEX( TP!C:C, MATCH( 1, (TP!A:A = A7) * (TP!B:B = C7), 0 ) )} -> 50.64 | E7: =sum(AH7,BO7) -> 7.412269 | F7: =PERCENTRANK(E$2:E$134,E7) -> 0.977 | G7: 6.7 | H7: =PERCENTRANK(G$2:G$134,G7) -> 0.076 | I7: =sum(G7-G$136)/G$137 -> -1.2972039 | J7: 97.1 | K7: =PERCENTRANK(J$2:J$134,J7) -> 0.333 | L7: =sum(J7-J$136)/J$137 -> -0.29607104 | M7: =(J7 * LOG(G7 + 1)) / LOG(MAX(G$2:G$134) + 1) * 100 -> 5788.731 | N7: =sum(M7-M$136)/M$137 -> -1.5937684 | O7: =PERCENTRANK(N$2:N$134,N7) -> 0.068 | P7: 6.73 | Q7: =PERCENTRANK(P$2:P$134,P7) -> 0.538 | R7: =sum(P7-P$136)/P$137 -> -0.093386688 | S7: 64.05 | T7: =PERCENTRANK(S$2:S$134,S7) -> 0.682 | U7: =sum(S7-S$136)/S$137 -> 0.59526782 | V7: =(S7 * LOG(P7 + 1)) / LOG(MAX(P$2:P$134) + 1) * 100 -> 4788.2034 | W7: =sum(V7-V$136)/V$137 -> 0.38824108 | X7: =PERCENTRANK(W$2:W$134,W7) -> 0.712 | Y7: 5.37 | Z7: =PERCENTRANK(Y$2:Y$134,Y7) -> 0.674 | AA7: =sum(Y7-Y$136)/Y$137 -> 0.27637058 | AB7: 82.38 | AC7: =PERCENTRANK(AB$2:AB$134,AB7) -> 0.977 | AD7: =sum(AB7-AB$136)/AB$137 -> 1.6671751 | AE7: =(AB7 * LOG(Y7 + 1)) / LOG(MAX(Y$2:Y$134) + 1) * 100 -> 6186.6327 | AF7: =sum(AE7-AE$136)/AE$137 -> 1.2383472 | AG7: =PERCENTRANK(AF$2:AF$134,AF7) -> 0.917 | AH7: =sum(AG7,X7,O7) -> 1.697 | AI7: =PERCENTRANK(AH$2:AH$134,AH7) -> 0.614 | AJ7: 0.7 | AK7: =PERCENTRANK(AJ$2:AJ$134,AJ7) -> 0.038 | AL7: =1-(AJ7-AJ$136)/AJ$137 -> 2.4247604 | AM7: 2.67 | AN7: =PERCENTRANK(AM$2:AM$134,AM7) -> 0.03 | AO7: =sum(AM7-AM$136)/AM$137 -> -1.3457565 | AP7: 73.96 | AQ7: =PERCENTRANK(AP$2:AP$134,AP7) -> 0.856 | AR7: =sum(AP7-AP$136)/AP$137 -> 1.0089283 | AS7: =(AP7 * LOG(AM7 + 1)) / LOG(MAX(AM$2:AM$134) + 1) * 100 -> 4575.4644 | AT7: =sum(AS7-AS$136)/AS$137 -> -0.69823747 | AU7: =PERCENTRANK(AT$2:AT$134,AT7) -> 0.227 | AV7: 0.009 | AW7: =PERCENTRANK(AV$2:AV$134,AV7) -> 0.621 | AX7: =sum(AV7-AV$136)/AV$137 -> 0.42808111 | AY7: 0.72 | AZ7: =PERCENTRANK(AY$2:AY$134,AY7) -> 0.879 | BA7: =sum(AY7-AY$136)/AY$137 -> 1.1093561 | BB7: =AY7 * (2/(1+EXP(-7*(($D7/100)-0.5)))) -> 0.7361253 | BC7: =PERCENTRANK(BB$2:BB$134,BB7) -> 0.902 | BD7: =sum(BB7-BB$136)/BB$137 -> 1.1705889 | BE7: 88.46 | BF7: =PERCENTRANK(BE$2:BE$134,BE7) -> 0.386 | BG7: =sum(BE7-BE$136)/BE$137 -> 0.027574134 | BH7: =(BE7 * LOG(BB7 + 1)) / LOG(MAX(BB$2:BB$134) + 1) * 100 -> 5375.4303 | BI7: =sum(BH7-BH$136)/BH$137 -> 1.0928947 | BJ7: =PERCENTRANK(BI$2:BI$134,BI7) -> 0.894 | BK7: 2.23 | BL7: =BK7 * (2/(1+EXP(-7*(($D7/100)-0.5)))) -> 2.2799436 | BM7: =PERCENTRANK(BL$2:BL$134,BL7) -> 0.947 | BN7: =sum(BL7-BL$136)/BK$137 -> 1.7695328 | BO7: =sum(AL7,AX7,BI7,BN7) -> 5.715269 | BP7: =PERCENTRANK(BO$2:BO$134,BO7) -> 0.962
A8: 2023 | B8: D. Jacomen | C8: Loudoun United | D8: {=INDEX( TP!C:C, MATCH( 1, (TP!A:A = A8) * (TP!B:B = C8), 0 ) )} -> 50.57 | E8: =sum(AH8,BO8) -> 6.9623005 | F8: =PERCENTRANK(E$2:E$134,E8) -> 0.947 | G8: 14.18 | H8: =PERCENTRANK(G$2:G$134,G8) -> 0.712 | I8: =sum(G8-G$136)/G$137 -> 0.2754768 | J8: 96.33 | K8: =PERCENTRANK(J$2:J$134,J8) -> 0.159 | L8: =sum(J8-J$136)/J$137 -> -0.89082653 | M8: =(J8 * LOG(G8 + 1)) / LOG(MAX(G$2:G$134) + 1) * 100 -> 7652.4646 | N8: =sum(M8-M$136)/M$137 -> 0.32782773 | O8: =PERCENTRANK(N$2:N$134,N8) -> 0.674 | P8: 9.09 | Q8: =PERCENTRANK(P$2:P$134,P8) -> 0.871 | R8: =sum(P8-P$136)/P$137 -> 1.0684133 | S8: 57.96 | T8: =PERCENTRANK(S$2:S$134,S8) -> 0.394 | U8: =sum(S8-S$136)/S$137 -> -0.27340665 | V8: =(S8 * LOG(P8 + 1)) / LOG(MAX(P$2:P$134) + 1) * 100 -> 4897.4242 | W8: =sum(V8-V$136)/V$137 -> 0.52231883 | X8: =PERCENTRANK(W$2:W$134,W8) -> 0.75 | Y8: 6.71 | Z8: =PERCENTRANK(Y$2:Y$134,Y8) -> 0.894 | AA8: =sum(Y8-Y$136)/Y$137 -> 1.2039556 | AB8: 56.9 | AC8: =PERCENTRANK(AB$2:AB$134,AB8) -> 0.091 | AD8: =sum(AB8-AB$136)/AB$137 -> -1.5283169 | AE8: =(AB8 * LOG(Y8 + 1)) / LOG(MAX(Y$2:Y$134) + 1) * 100 -> 4713.719 | AF8: =sum(AE8-AE$136)/AE$137 -> -0.2456252 | AG8: =PERCENTRANK(AF$2:AF$134,AF8) -> 0.371 | AH8: =sum(AG8,X8,O8) -> 1.795 | AI8: =PERCENTRANK(AH$2:AH$134,AH8) -> 0.667 | AJ8: 1.5 | AK8: =PERCENTRANK(AJ$2:AJ$134,AJ8) -> 0.803 | AL8: =1-(AJ8-AJ$136)/AJ$137 -> 0.39102674 | AM8: 4.46 | AN8: =PERCENTRANK(AM$2:AM$134,AM8) -> 0.803 | AO8: =sum(AM8-AM$136)/AM$137 -> 0.59867665 | AP8: 66.23 | AQ8: =PERCENTRANK(AP$2:AP$134,AP8) -> 0.364 | AR8: =sum(AP8-AP$136)/AP$137 -> -0.25248054 | AS8: =(AP8 * LOG(AM8 + 1)) / LOG(MAX(AM$2:AM$134) + 1) * 100 -> 5349.1199 | AT8: =sum(AS8-AS$136)/AS$137 -> 0.37530601 | AU8: =PERCENTRANK(AT$2:AT$134,AT8) -> 0.659 | AV8: 0.016 | AW8: =PERCENTRANK(AV$2:AV$134,AV8) -> 0.644 | AX8: =sum(AV8-AV$136)/AV$137 -> 0.46446781 | AY8: 1.45 | AZ8: =PERCENTRANK(AY$2:AY$134,AY8) -> 1 | BA8: =sum(AY8-AY$136)/AY$137 -> 4.2177944 | BB8: =AY8 * (2/(1+EXP(-7*(($D8/100)-0.5)))) -> 1.4789237 | BC8: =PERCENTRANK(BB$2:BB$134,BB8) -> 1 | BD8: =sum(BB8-BB$136)/BB$137 -> 4.2772997 | BE8: 68 | BF8: =PERCENTRANK(BE$2:BE$134,BE8) -> 0.061 | BG8: =sum(BE8-BE$136)/BE$137 -> -1.2004812 | BH8: =(BE8 * LOG(BB8 + 1)) / LOG(MAX(BB$2:BB$134) + 1) * 100 -> 6800 | BI8: =sum(BH8-BH$136)/BH$137 -> 1.9779004 | BJ8: =PERCENTRANK(BI$2:BI$134,BI8) -> 0.962 | BK8: 2.49 | BL8: =BK8 * (2/(1+EXP(-7*(($D8/100)-0.5)))) -> 2.5396689 | BM8: =PERCENTRANK(BL$2:BL$134,BL8) -> 0.977 | BN8: =sum(BL8-BL$136)/BK$137 -> 2.3339056 | BO8: =sum(AL8,AX8,BI8,BN8) -> 5.1673005 | BP8: =PERCENTRANK(BO$2:BO$134,BO8) -> 0.955
A9: 2024 | B9: E. Dick | C9: Pittsburgh Riverhounds | D9: {=INDEX( TP!C:C, MATCH( 1, (TP!A:A = A9) * (TP!B:B = C9), 0 ) )} -> 45.69 | E9: =sum(AH9,BO9) -> 5.4313238 | F9: =PERCENTRANK(E$2:E$134,E9) -> 0.886 | G9: 7.8 | H9: =PERCENTRANK(G$2:G$134,G9) -> 0.106 | I9: =sum(G9-G$136)/G$137 -> -1.0659273 | J9: 94.87 | K9: =PERCENTRANK(J$2:J$134,J9) -> 0.038 | L9: =sum(J9-J$136)/J$137 -> -2.0185447 | M9: =(J9 * LOG(G9 + 1)) / LOG(MAX(G$2:G$134) + 1) * 100 -> 6025.7739 | N9: =sum(M9-M$136)/M$137 -> -1.349366 | O9: =PERCENTRANK(N$2:N$134,N9) -> 0.083 | P9: 6.07 | Q9: =PERCENTRANK(P$2:P$134,P9) -> 0.348 | R9: =sum(P9-P$136)/P$137 -> -0.41829686 | S9: 59.89 | T9: =PERCENTRANK(S$2:S$134,S9) -> 0.485 | U9: =sum(S9-S$136)/S$137 -> 0.0018875601 | V9: =(S9 * LOG(P9 + 1)) / LOG(MAX(P$2:P$134) + 1) * 100 -> 4281.8279 | W9: =sum(V9-V$136)/V$137 -> -0.23337744 | X9: =PERCENTRANK(W$2:W$134,W9) -> 0.386 | Y9: 4.67 | Z9: =PERCENTRANK(Y$2:Y$134,Y9) -> 0.455 | AA9: =sum(Y9-Y$136)/Y$137 -> -0.20818876 | AB9: 70.71 | AC9: =PERCENTRANK(AB$2:AB$134,AB9) -> 0.545 | AD9: =sum(AB9-AB$136)/AB$137 -> 0.20361969 | AE9: =(AB9 * LOG(Y9 + 1)) / LOG(MAX(Y$2:Y$134) + 1) * 100 -> 4976.3755 | AF9: =sum(AE9-AE$136)/AE$137 -> 0.019003352 | AG9: =PERCENTRANK(AF$2:AF$134,AF9) -> 0.515 | AH9: =sum(AG9,X9,O9) -> 0.984 | AI9: =PERCENTRANK(AH$2:AH$134,AH9) -> 0.205 | AJ9: 0.63 | AK9: =PERCENTRANK(AJ$2:AJ$134,AJ9) -> 0 | AL9: =1-(AJ9-AJ$136)/AJ$137 -> 2.6027121 | AM9: 2.93 | AN9: =PERCENTRANK(AM$2:AM$134,AM9) -> 0.114 | AO9: =sum(AM9-AM$136)/AM$137 -> -1.0633249 | AP9: 78.41 | AQ9: =PERCENTRANK(AP$2:AP$134,AP9) -> 0.97 | AR9: =sum(AP9-AP$136)/AP$137 -> 1.7350951 | AS9: =(AP9 * LOG(AM9 + 1)) / LOG(MAX(AM$2:AM$134) + 1) * 100 -> 5106.1245 | AT9: =sum(AS9-AS$136)/AS$137 -> 0.038119565 | AU9: =PERCENTRANK(AT$2:AT$134,AT9) -> 0.485 | AV9: 0.211 | AW9: =PERCENTRANK(AV$2:AV$134,AV9) -> 0.955 | AX9: =sum(AV9-AV$136)/AV$137 -> 1.4780973 | AY9: 0.63 | AZ9: =PERCENTRANK(AY$2:AY$134,AY9) -> 0.773 | BA9: =sum(AY9-AY$136)/AY$137 -> 0.72612402 | BB9: =AY9 * (2/(1+EXP(-7*(($D9/100)-0.5)))) -> 0.53567887 | BC9: =PERCENTRANK(BB$2:BB$134,BB9) -> 0.659 | BD9: =sum(BB9-BB$136)/BB$137 -> 0.33223333 | BE9: 84.21 | BF9: =PERCENTRANK(BE$2:BE$134,BE9) -> 0.22 | BG9: =sum(BE9-BE$136)/BE$137 -> -0.22752046 | BH9: =(BE9 * LOG(BB9 + 1)) / LOG(MAX(BB$2:BB$134) + 1) * 100 -> 3979.1589 | BI9: =sum(BH9-BH$136)/BH$137 -> 0.22546912 | BJ9: =PERCENTRANK(BI$2:BI$134,BI9) -> 0.576 | BK9: 1.8 | BL9: =BK9 * (2/(1+EXP(-7*(($D9/100)-0.5)))) -> 1.530511 | BM9: =PERCENTRANK(BL$2:BL$134,BL9) -> 0.591 | BN9: =sum(BL9-BL$136)/BK$137 -> 0.14104531 | BO9: =sum(AL9,AX9,BI9,BN9) -> 4.4473238 | BP9: =PERCENTRANK(BO$2:BO$134,BO9) -> 0.917
A10: 2024 | B10: T. Deric | C10: Memphis 901 | D10: {=INDEX( TP!C:C, MATCH( 1, (TP!A:A = A10) * (TP!B:B = C10), 0 ) )} -> 50.52 | E10: =sum(AH10,BO10) -> 6.2787831 | F10: =PERCENTRANK(E$2:E$134,E10) -> 0.932 | G10: 10.74 | H10: =PERCENTRANK(G$2:G$134,G10) -> 0.303 | I10: =sum(G10-G$136)/G$137 -> -0.44778812 | J10: 98.26 | K10: =PERCENTRANK(J$2:J$134,J10) -> 0.712 | L10: =sum(J10-J$136)/J$137 -> 0.59992425 | M10: =(J10 * LOG(G10 + 1)) / LOG(MAX(G$2:G$134) + 1) * 100 -> 7068.3125 | N10: =sum(M10-M$136)/M$137 -> -0.27446022 | O10: =PERCENTRANK(N$2:N$134,N10) -> 0.341 | P10: 9.18 | Q10: =PERCENTRANK(P$2:P$134,P10) -> 0.879 | R10: =sum(P10-P$136)/P$137 -> 1.1127192 | S10: 62.93 | T10: =PERCENTRANK(S$2:S$134,S10) -> 0.644 | U10: =sum(S10-S$136)/S$137 -> 0.43551159 | V10: =(S10 * LOG(P10 + 1)) / LOG(MAX(P$2:P$134) + 1) * 100 -> 5337.8 | W10: =sum(V10-V$136)/V$137 -> 1.0629172 | X10: =PERCENTRANK(W$2:W$134,W10) -> 0.886 | Y10: 7.18 | Z10: =PERCENTRANK(Y$2:Y$134,Y10) -> 0.939 | AA10: =sum(Y10-Y$136)/Y$137 -> 1.5293026 | AB10: 73.04 | AC10: =PERCENTRANK(AB$2:AB$134,AB10) -> 0.636 | AD10: =sum(AB10-AB$136)/AB$137 -> 0.49582913 | AE10: =(AB10 * LOG(Y10 + 1)) / LOG(MAX(Y$2:Y$134) + 1) * 100 -> 6226.0895 | AF10: =sum(AE10-AE$136)/AE$137 -> 1.2781003 | AG10: =PERCENTRANK(AF$2:AF$134,AF10) -> 0.924 | AH10: =sum(AG10,X10,O10) -> 2.151 | AI10: =PERCENTRANK(AH$2:AH$134,AH10) -> 0.841 | AJ10: 1.06 | AK10: =PERCENTRANK(AJ$2:AJ$134,AJ10) -> 0.341 | AL10: =1-(AJ10-AJ$136)/AJ$137 -> 1.5095803 | AM10: 3.44 | AN10: =PERCENTRANK(AM$2:AM$134,AM10) -> 0.333 | AO10: =sum(AM10-AM$136)/AM$137 -> -0.50932436 | AP10: 69.09 | AQ10: =PERCENTRANK(AP$2:AP$134,AP10) -> 0.568 | AR10: =sum(AP10-AP$136)/AP$137 -> 0.21422442 | AS10: =(AP10 * LOG(AM10 + 1)) / LOG(MAX(AM$2:AM$134) + 1) * 100 -> 4900.3043 | AT10: =sum(AS10-AS$136)/AS$137 -> -0.24748158 | AU10: =PERCENTRANK(AT$2:AT$134,AT10) -> 0.386 | AV10: 0.035 | AW10: =PERCENTRANK(AV$2:AV$134,AV10) -> 0.705 | AX10: =sum(AV10-AV$136)/AV$137 -> 0.56323171 | AY10: 0.62 | AZ10: =PERCENTRANK(AY$2:AY$134,AY10) -> 0.765 | BA10: =sum(AY10-AY$136)/AY$137 -> 0.68354267 | BB10: =AY10 * (2/(1+EXP(-7*(($D10/100)-0.5)))) -> 0.63128275 | BC10: =PERCENTRANK(BB$2:BB$134,BB10) -> 0.826 | BD10: =sum(BB10-BB$136)/BB$137 -> 0.73209102 | BE10: 100 | BF10: =PERCENTRANK(BE$2:BE$134,BE10) -> 0.697 | BG10: =sum(BE10-BE$136)/BE$137 -> 0.72023098 | BH10: =(BE10 * LOG(BB10 + 1)) / LOG(MAX(BB$2:BB$134) + 1) * 100 -> 5390.5429 | BI10: =sum(BH10-BH$136)/BH$137 -> 1.1022833 | BJ10: =PERCENTRANK(BI$2:BI$134,BI10) -> 0.902 | BK10: 1.87 | BL10: =BK10 * (2/(1+EXP(-7*(($D10/100)-0.5)))) -> 1.9040302 | BM10: =PERCENTRANK(BL$2:BL$134,BL10) -> 0.826 | BN10: =sum(BL10-BL$136)/BK$137 -> 0.9526878 | BO10: =sum(AL10,AX10,BI10,BN10) -> 4.1277831 | BP10: =PERCENTRANK(BO$2:BO$134,BO10) -> 0.879
A11: 2024 | B11: R. Arozarena | C11: Las Vegas Lights | D11: {=INDEX( TP!C:C, MATCH( 1, (TP!A:A = A11) * (TP!B:B = C11), 0 ) )} -> 59.94 | E11: =sum(AH11,BO11) -> 7.9497241 | F11: =PERCENTRANK(E$2:E$134,E11) -> 0.985 | G11: 15.65 | H11: =PERCENTRANK(G$2:G$134,G11) -> 0.818 | I11: =sum(G11-G$136)/G$137 -> 0.5845464 | J11: 97.84 | K11: =PERCENTRANK(J$2:J$134,J11) -> 0.545 | L11: =sum(J11-J$136)/J$137 -> 0.27551216 | M11: =(J11 * LOG(G11 + 1)) / LOG(MAX(G$2:G$134) + 1) * 100 -> 8036.5447 | N11: =sum(M11-M$136)/M$137 -> 0.72383221 | O11: =PERCENTRANK(N$2:N$134,N11) -> 0.818 | P11: 5.34 | Q11: =PERCENTRANK(P$2:P$134,P11) -> 0.22 | R11: =sum(P11-P$136)/P$137 -> -0.77766719 | S11: 50.63 | T11: =PERCENTRANK(S$2:S$134,S11) -> 0.083 | U11: =sum(S11-S$136)/S$137 -> -1.3189541 | V11: =(S11 * LOG(P11 + 1)) / LOG(MAX(P$2:P$134) + 1) * 100 -> 3418.0888 | W11: =sum(V11-V$136)/V$137 -> -1.2936899 | X11: =PERCENTRANK(W$2:W$134,W11) -> 0.091 | Y11: 3.68 | Z11: =PERCENTRANK(Y$2:Y$134,Y11) -> 0.182 | AA11: =sum(Y11-Y$136)/Y$137 -> -0.8934941 | AB11: 55.96 | AC11: =PERCENTRANK(AB$2:AB$134,AB11) -> 0.083 | AD11: =sum(AB11-AB$136)/AB$137 -> -1.646204 | AE11: =(AB11 * LOG(Y11 + 1)) / LOG(MAX(Y$2:Y$134) + 1) * 100 -> 3502.7813 | AF11: =sum(AE11-AE$136)/AE$137 -> -1.4656548 | AG11: =PERCENTRANK(AF$2:AF$134,AF11) -> 0.098 | AH11: =sum(AG11,X11,O11) -> 1.007 | AI11: =PERCENTRANK(AH$2:AH$134,AH11) -> 0.212 | AJ11: 1.01 | AK11: =PERCENTRANK(AJ$2:AJ$134,AJ11) -> 0.25 | AL11: =1-(AJ11-AJ$136)/AJ$137 -> 1.6366886 | AM11: 3.92 | AN11: =PERCENTRANK(AM$2:AM$134,AM11) -> 0.568 | AO11: =sum(AM11-AM$136)/AM$137 -> 0.012087878 | AP11: 74.14 | AQ11: =PERCENTRANK(AP$2:AP$134,AP11) -> 0.864 | AR11: =sum(AP11-AP$136)/AP$137 -> 1.0383014 | AS11: =(AP11 * LOG(AM11 + 1)) / LOG(MAX(AM$2:AM$134) + 1) * 100 -> 5620.6088 | AT11: =sum(AS11-AS$136)/AS$137 -> 0.7520307 | AU11: =PERCENTRANK(AT$2:AT$134,AT11) -> 0.788 | AV11: 0.192 | AW11: =PERCENTRANK(AV$2:AV$134,AV11) -> 0.939 | AX11: =sum(AV11-AV$136)/AV$137 -> 1.3793334 | AY11: 0.78 | AZ11: =PERCENTRANK(AY$2:AY$134,AY11) -> 0.939 | BA11: =sum(AY11-AY$136)/AY$137 -> 1.3648442 | BB11: =AY11 * (2/(1+EXP(-7*(($D11/100)-0.5)))) -> 1.0409192 | BC11: =PERCENTRANK(BB$2:BB$134,BB11) -> 0.985 | BD11: =sum(BB11-BB$136)/BB$137 -> 2.4453717 | BE11: 91.3 | BF11: =PERCENTRANK(BE$2:BE$134,BE11) -> 0.485 | BG11: =sum(BE11-BE$136)/BE$137 -> 0.19803734 | BH11: =(BE11 * LOG(BB11 + 1)) / LOG(MAX(BB$2:BB$134) + 1) * 100 -> 7174.6743 | BI11: =sum(BH11-BH$136)/BH$137 -> 2.2106646 | BJ11: =PERCENTRANK(BI$2:BI$134,BI11) -> 0.977 | BK11: 1.69 | BL11: =BK11 * (2/(1+EXP(-7*(($D11/100)-0.5)))) -> 2.255325 | BM11: =PERCENTRANK(BL$2:BL$134,BL11) -> 0.939 | BN11: =sum(BL11-BL$136)/BK$137 -> 1.7160375 | BO11: =sum(AL11,AX11,BI11,BN11) -> 6.9427241 | BP11: =PERCENTRANK(BO$2:BO$134,BO11) -> 1
A12: 2025 | B12: D. Vitiello | C12: Sacramento Republic | D12: {=INDEX( TP!C:C, MATCH( 1, (TP!A:A = A12) * (TP!B:B = C12), 0 ) )} -> 46.29 | E12: =sum(AH12,BO12) -> 4.9341577 | F12: =PERCENTRANK(E$2:E$134,E12) -> 0.841 | G12: 7.86 | H12: =PERCENTRANK(G$2:G$134,G12) -> 0.129 | I12: =sum(G12-G$136)/G$137 -> -1.0533122 | J12: 97.81 | K12: =PERCENTRANK(J$2:J$134,J12) -> 0.515 | L12: =sum(J12-J$136)/J$137 -> 0.25233987 | M12: =(J12 * LOG(G12 + 1)) / LOG(MAX(G$2:G$134) + 1) * 100 -> 6231.9224 | N12: =sum(M12-M$136)/M$137 -> -1.1368174 | O12: =PERCENTRANK(N$2:N$134,N12) -> 0.129 | P12: 4.79 | Q12: =PERCENTRANK(P$2:P$134,P12) -> 0.106 | R12: =sum(P12-P$136)/P$137 -> -1.0484257 | S12: 58.68 | T12: =PERCENTRANK(S$2:S$134,S12) -> 0.417 | U12: =sum(S12-S$136)/S$137 -> -0.17070622 | V12: =(S12 * LOG(P12 + 1)) / LOG(MAX(P$2:P$134) + 1) * 100 -> 3766.9023 | W12: =sum(V12-V$136)/V$137 -> -0.86549196 | X12: =PERCENTRANK(W$2:W$134,W12) -> 0.212 | Y12: 3.53 | Z12: =PERCENTRANK(Y$2:Y$134,Y12) -> 0.121 | AA12: =sum(Y12-Y$136)/Y$137 -> -0.99732825 | AB12: 78.05 | AC12: =PERCENTRANK(AB$2:AB$134,AB12) -> 0.886 | AD12: =sum(AB12-AB$136)/AB$137 -> 1.1241421 | AE12: =(AB12 * LOG(Y12 + 1)) / LOG(MAX(Y$2:Y$134) + 1) * 100 -> 4782.3674 | AF12: =sum(AE12-AE$136)/AE$137 -> -0.17646141 | AG12: =PERCENTRANK(AF$2:AF$134,AF12) -> 0.417 | AH12: =sum(AG12,X12,O12) -> 0.758 | AI12: =PERCENTRANK(AH$2:AH$134,AH12) -> 0.114 | AJ12: 0.77 | AK12: =PERCENTRANK(AJ$2:AJ$134,AJ12) -> 0.061 | AL12: =1-(AJ12-AJ$136)/AJ$137 -> 2.2468087 | AM12: 2.78 | AN12: =PERCENTRANK(AM$2:AM$134,AM12) -> 0.038 | AO12: =sum(AM12-AM$136)/AM$137 -> -1.2262662 | AP12: 72.16 | AQ12: =PERCENTRANK(AP$2:AP$134,AP12) -> 0.788 | AR12: =sum(AP12-AP$136)/AP$137 -> 0.71519793 | AS12: =(AP12 * LOG(AM12 + 1)) / LOG(MAX(AM$2:AM$134) + 1) * 100 -> 4565.5062 | AT12: =sum(AS12-AS$136)/AS$137 -> -0.71205572 | AU12: =PERCENTRANK(AT$2:AT$134,AT12) -> 0.22 | AV12: 0.097 | AW12: =PERCENTRANK(AV$2:AV$134,AV12) -> 0.833 | AX12: =sum(AV12-AV$136)/AV$137 -> 0.8855139 | AY12: 0.69 | AZ12: =PERCENTRANK(AY$2:AY$134,AY12) -> 0.848 | BA12: =sum(AY12-AY$136)/AY$137 -> 0.9816121 | BB12: =AY12 * (2/(1+EXP(-7*(($D12/100)-0.5)))) -> 0.60090369 | BC12: =PERCENTRANK(BB$2:BB$134,BB12) -> 0.773 | BD12: =sum(BB12-BB$136)/BB$137 -> 0.60503235 | BE12: 100 | BF12: =PERCENTRANK(BE$2:BE$134,BE12) -> 0.697 | BG12: =sum(BE12-BE$136)/BE$137 -> 0.72023098 | BH12: =(BE12 * LOG(BB12 + 1)) / LOG(MAX(BB$2:BB$134) + 1) * 100 -> 5183.4721 | BI12: =sum(BH12-BH$136)/BH$137 -> 0.97364175 | BJ12: =PERCENTRANK(BI$2:BI$134,BI12) -> 0.856 | BK12: 1.72 | BL12: =BK12 * (2/(1+EXP(-7*(($D12/100)-0.5)))) -> 1.4979049 | BM12: =PERCENTRANK(BL$2:BL$134,BL12) -> 0.53 | BN12: =sum(BL12-BL$136)/BK$137 -> 0.070193334 | BO12: =sum(AL12,AX12,BI12,BN12) -> 4.1761577 | BP12: =PERCENTRANK(BO$2:BO$134,BO12) -> 0.894
A13: 2024 | B13: D. Vitiello | C13: Sacramento Republic | D13: {=INDEX( TP!C:C, MATCH( 1, (TP!A:A = A13) * (TP!B:B = C13), 0 ) )} -> 49.69 | E13: =sum(AH13,BO13) -> 5.7175231 | F13: =PERCENTRANK(E$2:E$134,E13) -> 0.902 | G13: 12.75 | H13: =PERCENTRANK(G$2:G$134,G13) -> 0.606 | I13: =sum(G13-G$136)/G$137 -> -0.025182747 | J13: 96.28 | K13: =PERCENTRANK(J$2:J$134,J13) -> 0.152 | L13: =sum(J13-J$136)/J$137 -> -0.92944702 | M13: =(J13 * LOG(G13 + 1)) / LOG(MAX(G$2:G$134) + 1) * 100 -> 7370.2766 | N13: =sum(M13-M$136)/M$137 -> 0.036878819 | O13: =PERCENTRANK(N$2:N$134,N13) -> 0.53 | P13: 6.14 | Q13: =PERCENTRANK(P$2:P$134,P13) -> 0.371 | R13: =sum(P13-P$136)/P$137 -> -0.38383669 | S13: 57.27 | T13: =PERCENTRANK(S$2:S$134,S13) -> 0.364 | U13: =sum(S13-S$136)/S$137 -> -0.37182789 | V13: =(S13 * LOG(P13 + 1)) / LOG(MAX(P$2:P$134) + 1) * 100 -> 4115.1367 | W13: =sum(V13-V$136)/V$137 -> -0.43800492 | X13: =PERCENTRANK(W$2:W$134,W13) -> 0.333 | Y13: 4.49 | Z13: =PERCENTRANK(Y$2:Y$134,Y13) -> 0.409 | AA13: =sum(Y13-Y$136)/Y$137 -> -0.33278973 | AB13: 75.78 | AC13: =PERCENTRANK(AB$2:AB$134,AB13) -> 0.758 | AD13: =sum(AB13-AB$136)/AB$137 -> 0.8394574 | AE13: =(AB13 * LOG(Y13 + 1)) / LOG(MAX(Y$2:Y$134) + 1) * 100 -> 5234.0329 | AF13: =sum(AE13-AE$136)/AE$137 -> 0.27859521 | AG13: =PERCENTRANK(AF$2:AF$134,AF13) -> 0.606 | AH13: =sum(AG13,X13,O13) -> 1.469 | AI13: =PERCENTRANK(AH$2:AH$134,AH13) -> 0.477 | AJ13: 0.84 | AK13: =PERCENTRANK(AJ$2:AJ$134,AJ13) -> 0.091 | AL13: =1-(AJ13-AJ$136)/AJ$137 -> 2.068857 | AM13: 3.68 | AN13: =PERCENTRANK(AM$2:AM$134,AM13) -> 0.455 | AO13: =sum(AM13-AM$136)/AM$137 -> -0.24861824 | AP13: 77.27 | AQ13: =PERCENTRANK(AP$2:AP$134,AP13) -> 0.947 | AR13: =sum(AP13-AP$136)/AP$137 -> 1.5490659 | AS13: =(AP13 * LOG(AM13 + 1)) / LOG(MAX(AM$2:AM$134) + 1) * 100 -> 5674.0301 | AT13: =sum(AS13-AS$136)/AS$137 -> 0.82615936 | AU13: =PERCENTRANK(AT$2:AT$134,AT13) -> 0.811 | AV13: 0.12 | AW13: =PERCENTRANK(AV$2:AV$134,AV13) -> 0.879 | AX13: =sum(AV13-AV$136)/AV$137 -> 1.0050702 | AY13: 0.56 | AZ13: =PERCENTRANK(AY$2:AY$134,AY13) -> 0.667 | BA13: =sum(AY13-AY$136)/AY$137 -> 0.42805459 | BB13: =AY13 * (2/(1+EXP(-7*(($D13/100)-0.5)))) -> 0.55392424 | BC13: =PERCENTRANK(BB$2:BB$134,BB13) -> 0.689 | BD13: =sum(BB13-BB$136)/BB$137 -> 0.40854354 | BE13: 100 | BF13: =PERCENTRANK(BE$2:BE$134,BE13) -> 0.697 | BG13: =sum(BE13-BE$136)/BE$137 -> 0.72023098 | BH13: =(BE13 * LOG(BB13 + 1)) / LOG(MAX(BB$2:BB$134) + 1) * 100 -> 4855.3825 | BI13: =sum(BH13-BH$136)/BH$137 -> 0.76981797 | BJ13: =PERCENTRANK(BI$2:BI$134,BI13) -> 0.795 | BK13: 1.67 | BL13: =BK13 * (2/(1+EXP(-7*(($D13/100)-0.5)))) -> 1.6518812 | BM13: =PERCENTRANK(BL$2:BL$134,BL13) -> 0.674 | BN13: =sum(BL13-BL$136)/BK$137 -> 0.40477789 | BO13: =sum(AL13,AX13,BI13,BN13) -> 4.2485231 | BP13: =PERCENTRANK(BO$2:BO$134,BO13) -> 0.902
... A134: 2024 | B134: F. Rodriguez | C134: Miami | D134: {=INDEX( TP!C:C, MATCH( 1, (TP!A:A = A134) * (TP!B:B = C134), 0 ) )} -> 44.7 | E134: =sum(AH134,BO134) -> -7.5545773 | F134: =PERCENTRANK(E$2:E$134,E134) -> 0 | G134: 14.41 | H134: =PERCENTRANK(G$2:G$134,G134) -> 0.727 | I134: =sum(G134-G$136)/G$137 -> 0.32383463 | J134: 96.88 | K134: =PERCENTRANK(J$2:J$134,J134) -> 0.258 | L134: =sum(J134-J$136)/J$137 -> -0.46600118 | M134: =(J134 * LOG(G134 + 1)) / LOG(MAX(G$2:G$134) + 1) * 100 -> 7738.7061 | N134: =sum(M134-M$136)/M$137 -> 0.41674684 | O134: =PERCENTRANK(N$2:N$134,N134) -> 0.697 | P134: 5.68 | Q134: =PERCENTRANK(P$2:P$134,P134) -> 0.295 | R134: =sum(P134-P$136)/P$137 -> -0.61028923 | S134: 53.97 | T134: =PERCENTRANK(S$2:S$134,S134) -> 0.212 | U134: =sum(S134-S$136)/S$137 -> -0.84253819 | V134: =(S134 * LOG(P134 + 1)) / LOG(MAX(P$2:P$134) + 1) * 100 -> 3746.6351 | W134: =sum(V134-V$136)/V$137 -> -0.89037175 | X134: =PERCENTRANK(W$2:W$134,W134) -> 0.197 | Y134: 3.78 | Z134: =PERCENTRANK(Y$2:Y$134,Y134) -> 0.22 | AA134: =sum(Y134-Y$136)/Y$137 -> -0.82427134 | AB134: 64.29 | AC134: =PERCENTRANK(AB$2:AB$134,AB134) -> 0.227 | AD134: =sum(AB134-AB$136)/AB$137 -> -0.60152391 | AE134: =(AB134 * LOG(Y134 + 1)) / LOG(MAX(Y$2:Y$134) + 1) * 100 -> 4079.322 | AF134: =sum(AE134-AE$136)/AE$137 -> -0.8847854 | AG134: =PERCENTRANK(AF$2:AF$134,AF134) -> 0.159 | AH134: =sum(AG134,X134,O134) -> 1.053 | AI134: =PERCENTRANK(AH$2:AH$134,AH134) -> 0.258 | AJ134: 3.15 | AK134: =PERCENTRANK(AJ$2:AJ$134,AJ134) -> 1 | AL134: =1-(AJ134-AJ$136)/AJ$137 -> -3.803549 | AM134: 6.31 | AN134: =PERCENTRANK(AM$2:AM$134,AM134) -> 0.985 | AO134: =sum(AM134-AM$136)/AM$137 -> 2.6082863 | AP134: 50 | AQ134: =PERCENTRANK(AP$2:AP$134,AP134) -> 0.008 | AR134: =sum(AP134-AP$136)/AP$137 -> -2.9009496 | AS134: =(AP134 * LOG(AM134 + 1)) / LOG(MAX(AM$2:AM$134) + 1) * 100 -> 4732.4801 | AT134: =sum(AS134-AS$136)/AS$137 -> -0.48035851 | AU134: =PERCENTRANK(AT$2:AT$134,AT134) -> 0.311 | AV134: -0.768 | AW134: =PERCENTRANK(AV$2:AV$134,AV134) -> 0 | AX134: =sum(AV134-AV$136)/AV$137 -> -3.6108425 | AY134: 0.27 | AZ134: =PERCENTRANK(AY$2:AY$134,AY134) -> 0.212 | BA134: =sum(AY134-AY$136)/AY$137 -> -0.80680446 | BB134: =AY134 * (2/(1+EXP(-7*(($D134/100)-0.5)))) -> 0.22048168 | BC134: =PERCENTRANK(BB$2:BB$134,BB134) -> 0.129 | BD134: =sum(BB134-BB$136)/BB$137 -> -0.98606053 | BE134: 100 | BF134: =PERCENTRANK(BE$2:BE$134,BE134) -> 0.697 | BG134: =sum(BE134-BE$136)/BE$137 -> 0.72023098 | BH134: =(BE134 * LOG(BB134 + 1)) / LOG(MAX(BB$2:BB$134) + 1) * 100 -> 2194.7591 | BI134: =sum(BH134-BH$136)/BH$137 -> -0.88307894 | BJ134: =PERCENTRANK(BI$2:BI$134,BI134) -> 0.182 | BK134: 1.62 | BL134: =BK134 * (2/(1+EXP(-7*(($D134/100)-0.5)))) -> 1.3228901 | BM134: =PERCENTRANK(BL$2:BL$134,BL134) -> 0.386 | BN134: =sum(BL134-BL$136)/BK$137 -> -0.31010685 | BO134: =sum(AL134,AX134,BI134,BN134) -> -8.6075773 | BP134: =PERCENTRANK(BO$2:BO$134,BO134) -> 0
B136: Mean | E136: =AVERAGE(E2:E134) -> 2.4998346 | G136: =AVERAGE(G2:G134) -> 12.869774 | J136: =AVERAGE(J2:J134) -> 97.483308 | M136: =AVERAGE(M2:M134) -> 7334.5083 | N136: =AVERAGE(N2:N134) -> 0 | P136: =AVERAGE(P2:P134) -> 6.9196992 | S136: =AVERAGE(S2:S134) -> 59.876767 | V136: =AVERAGE(V2:V134) -> 4471.9391 | W136: =AVERAGE(W2:W134) -> 0 | Y136: =AVERAGE(Y2:Y134) -> 4.9707519 | AB136: =AVERAGE(AB2:AB134) -> 69.086391 | AE136: =AVERAGE(AE2:AE134) -> 4957.5138 | AF136: =AVERAGE(AF2:AF134) -> 0 | AH136: =AVERAGE(AH2:AH134) -> 1.4998346 | AJ136: =AVERAGE(AJ2:AJ134) -> 1.2604511 | AM136: =AVERAGE(AM2:AM134) -> 3.9088722 | AP136: =AVERAGE(AP2:AP134) -> 67.777218 | AS136: =AVERAGE(AS2:AS134) -> 5078.6534 | AV136: =AVERAGE(AV2:AV134) -> -0.073353383 | AY136: =AVERAGE(AY2:AY134) -> 0.45947368 | BB136: =AVERAGE(BB2:BB134) -> 0.45624361 | BE136: =AVERAGE(BE2:BE134) -> 88.000602 | BH136: =AVERAGE(BH2:BH134) -> 3616.2274 | BI136: =AVERAGE(BI2:BI134) -> 0 | BK136: =AVERAGE(BK2:BK134) -> 1.4809023 | BL136: =AVERAGE(BL2:BL134) -> 1.4656018 | BO136: =AVERAGE(BO2:BO134) -> 1
B137: STDEV | E137: =STDEV(E2:E134) -> 2.6680585 | G137: =STDEV(G2:G134) -> 4.7562102 | J137: =STDEV(J2:J134) -> 1.2946497 | M137: =STDEV(M2:M134) -> 969.88829 | N137: =STDEV(N2:N134) -> 1 | P137: =STDEV(P2:P134) -> 2.0313307 | S137: =STDEV(S2:S134) -> 7.0106815 | V137: =STDEV(V2:V134) -> 814.60809 | W137: =STDEV(W2:W134) -> 1 | Y137: =STDEV(Y2:Y134) -> 1.4446115 | AB137: =STDEV(AB2:AB134) -> 7.9737329 | AE137: =STDEV(AE2:AE134) -> 992.54785 | AF137: =STDEV(AF2:AF134) -> 1 | AH137: =STDEV(AH2:AH134) -> 0.59451462 | AJ137: =STDEV(AJ2:AJ134) -> 0.39336517 | AM137: =STDEV(AM2:AM134) -> 0.92057677 | AP137: =STDEV(AP2:AP134) -> 6.1280686 | AS137: =STDEV(AS2:AS134) -> 720.656 | AV137: =STDEV(AV2:AV134) -> 0.19237799 | AY137: =STDEV(AY2:AY134) -> 0.23484462 | BB137: =STDEV(BB2:BB134) -> 0.23909478 | BE137: =STDEV(BE2:BE134) -> 16.660487 | BH137: =STDEV(BH2:BH134) -> 1609.6729 | BI137: =STDEV(BI2:BI134) -> 1 | BK137: =STDEV(BK2:BK134) -> 0.46020163 | BL137: =STDEV(BL2:BL134) -> 0.46455925 | BO137: =STDEV(BO2:BO134) -> 2.5700562

Sheet CB
A1: Season | B1: 900+ minutes | C1: Team | D1: Possession | E1: Total STDEV | F1: Overall Rank | H1: Defensive duels per 90 | K1: Padj Defensive duels per 90 | N1: Defensive duels won, % | R1: Defensive duels Impact | U1: Padj Aerial duels per 90 | X1: Aerial duels won, % | AB1: PAdj Aerial Duel Impact | AD1: PAdj Interceptions | AF1: Defensive Impact Stdev | AG1: Defenive Impact Percentile | AI1: Lateral Passes per 90 | AL1: Lateral Accurate passes, % | AP1: Lateral Passing Impact | AR1: Forward passes per 90 | AU1: Accurate forward passes, % | AY1: Forward Passing Impact | BA1: Long Passes p90 | BD1: Long passes, % | BH1: Long passes Impact | BJ1: Progressive passes per 90 | BM1: Accurate progressive passes, % | BQ1: Progressive passes Impact | BR1: Passing Impact Stdev | BS1: Passing Impact Percentile
A2: 2022 | B2: N. Cobb | C2: Atlanta United II | D2: {=INDEX( TP!C:C, MATCH( 1, (TP!A:A = A2) * (TP!B:B = C2), 0 ) )} -> 49.82 | E2: =sum(AF2,BR2) -> 3.6302289 | F2: =PERCENTRANK(E$2:E$356,E2) -> 0.833 | G2: 6.78 | H2: =PERCENTRANK(G$2:G$356,G2) -> 0.845 | I2: =sum(G2-G$358)/G$359 -> 1.0391562 | J2: =G2 * (2/(1+EXP(-7*(($D2/100)-0.5)))) -> 6.7372866 | K2: =PERCENTRANK(J$2:J$356,J2) -> 0.83 | L2: =sum(J2-J$358)/J$359 -> 0.99915993 | M2: 68.48 | N2: =PERCENTRANK(M$2:M$356,M2) -> 0.695 | O2: =sum(M2-M$358)/M$359 -> 0.4403789 | P2: =(M2 * LOG(J2 + 1)) / LOG(MAX(J$2:J$356) + 1) * 100 -> 5927.2994 | Q2: =sum(P2-P$358)/P$359 -> 1.1105664 | R2: =PERCENTRANK(Q$2:Q$356,Q2) -> 0.856 | S2: 2.42 | T2: =S2 * (2/(1+EXP(-7*(($D2/100)-0.5)))) -> 2.4047542 | U2: =PERCENTRANK(T$2:T$356,T2) -> 0.119 | V2: =sum(S2-S$358)/S$359 -> -1.2211709 | W2: 59.32 | X2: =PERCENTRANK(W$2:W$356,W2) -> 0.483 | Y2: =sum(W2-W$358)/W$359 -> 0.073474665 | Z2: =(W2 * LOG(T2 + 1)) / LOG(MAX(T$2:T$356) + 1) * 100 -> 3513.8561 | AA2: =sum(Z2-Z$358)/Z$359 -> -0.79976773 | AB2: =PERCENTRANK(AA$2:AA$356,AA2) -> 0.218 | AC2: 8.93 | AD2: =PERCENTRANK(AC$2:AC$356,AC2) -> 0.966 | AE2: =sum(AC2-AC$358)/AC$359 -> 2.0189894 | AF2: =sum(Q2,AA2,AE2) -> 2.3297881 | AG2: =PERCENTRANK(AF$2:AF$356,AF2) -> 0.881 | AH2: 22.3 | AI2: =PERCENTRANK(AH$2:AH$356,AH2) -> 0.791 | AJ2: =sum(AH2-AH$358)/AH$359 -> 0.74072722 | AK2: 94.29 | AL2: =PERCENTRANK(AK$2:AK$356,AK2) -> 0.432 | AM2: =sum(AK2-AK$358)/AK$359 -> 0.074276446 | AN2: =(AK2 * LOG(AH2 + 1)) / LOG(MAX(AH$2:AH$356) + 1) * 100 -> 8356.6156 | AO2: =sum(AN2-AN$358)/AN$359 -> 0.61805409 | AP2: =PERCENTRANK(AO$2:AO$356,AO2) -> 0.74 | AQ2: 20.5 | AR2: =PERCENTRANK(AQ$2:AQ$356,AQ2) -> 0.768 | AS2: =sum(AQ2-AQ$358)/AQ$359 -> 0.70284135 | AT2: 71.54 | AU2: =PERCENTRANK(AT$2:AT$356,AT2) -> 0.28 | AV2: =sum(AT2-AT$358)/AT$359 -> -0.50001259 | AW2: =(AT2 * LOG(AQ2 + 1)) / LOG(MAX(AQ$2:AQ$356) + 1) * 100 -> 6361.4234 | AX2: =sum(AW2-AW$358)/AW$359 -> 0.024577455 | AY2: =PERCENTRANK(AX$2:AX$356,AX2) -> 0.497 | AZ2: 8.63 | BA2: =PERCENTRANK(AZ$2:AZ$356,AZ2) -> 0.91 | BB2: =sum(AZ2-AZ$358)/AZ$359 -> 1.4227658 | BC2: 54.76 | BD2: =PERCENTRANK(BC$2:BC$356,BC2) -> 0.686 | BE2: =sum(BC2-BC$358)/BC$359 -> 0.55692192 | BF2: =(BC2 * LOG(AZ2 + 1)) / LOG(MAX(AZ$2:AZ$356) + 1) * 100 -> 4727.9713 | BG2: =sum(BF2-BF$358)/BF$359 -> 1.3506553 | BH2: =PERCENTRANK(BG$2:BG$356,BG2) -> 0.924 | BI2: 9.49 | BJ2: =PERCENTRANK(BI$2:BI$356,BI2) -> 0.774 | BK2: =sum(BI2-BI$358)/BI$359 -> 0.79919835 | BL2: 56.71 | BM2: =PERCENTRANK(BL$2:BL$356,BL2) -> 0.034 | BN2: =sum(BL2-BL$358)/BL$359 -> -1.7753783 | BO2: =(BL2 * LOG(BI2 + 1)) / LOG(MAX(BI$2:BI$356) + 1) * 100 -> 4854.08 | BP2: =sum(BO2-BO$358)/BO$359 -> -0.69284606 | BQ2: =PERCENTRANK(BP$2:BP$356,BP2) -> 0.229 | BR2: =sum(AO2,AX2,BG2,BP2) -> 1.3004408 | BS2: =PERCENTRANK(BR$2:BR$356,BR2) -> 0.667
A3: 2022 | B3: O. Chukwuma | C3: Atlanta United II | D3: {=INDEX( TP!C:C, MATCH( 1, (TP!A:A = A3) * (TP!B:B = C3), 0 ) )} -> 49.82 | E3: =sum(AF3,BR3) -> 0.40741994 | F3: =PERCENTRANK(E$2:E$356,E3) -> 0.525 | G3: 8.71 | H3: =PERCENTRANK(G$2:G$356,G3) -> 0.986 | I3: =sum(G3-G$358)/G$359 -> 2.4340153 | J3: =G3 * (2/(1+EXP(-7*(($D3/100)-0.5)))) -> 8.6551277 | K3: =PERCENTRANK(J$2:J$356,J3) -> 0.986 | L3: =sum(J3-J$358)/J$359 -> 2.3304351 | M3: 59.28 | N3: =PERCENTRANK(M$2:M$356,M3) -> 0.102 | O3: =sum(M3-M$358)/M$359 -> -1.1677491 | P3: =(M3 * LOG(J3 + 1)) / LOG(MAX(J$2:J$356) + 1) * 100 -> 5686.3038 | Q3: =sum(P3-P$358)/P$359 -> 0.80757482 | R3: =PERCENTRANK(Q$2:Q$356,Q3) -> 0.802 | S3: 2.66 | T3: =S3 * (2/(1+EXP(-7*(($D3/100)-0.5)))) -> 2.6432422 | U3: =PERCENTRANK(T$2:T$356,T3) -> 0.164 | V3: =sum(S3-S$358)/S$359 -> -1.0089579 | W3: 47.06 | X3: =PERCENTRANK(W$2:W$356,W3) -> 0.09 | Y3: =sum(W3-W$358)/W$359 -> -1.3337147 | Z3: =(W3 * LOG(T3 + 1)) / LOG(MAX(T$2:T$356) + 1) * 100 -> 2941.6678 | AA3: =sum(Z3-Z$358)/Z$359 -> -1.3232624 | AB3: =PERCENTRANK(AA$2:AA$356,AA3) -> 0.099 | AC3: 8.18 | AD3: =PERCENTRANK(AC$2:AC$356,AC3) -> 0.91 | AE3: =sum(AC3-AC$358)/AC$359 -> 1.4184152 | AF3: =sum(Q3,AA3,AE3) -> 0.90272769 | AG3: =PERCENTRANK(AF$2:AF$356,AF3) -> 0.667 | AH3: 14.82 | AI3: =PERCENTRANK(AH$2:AH$356,AH3) -> 0.203 | AJ3: =sum(AH3-AH$358)/AH$359 -> -0.70355679 | AK3: 93.31 | AL3: =PERCENTRANK(AK$2:AK$356,AK3) -> 0.299 | AM3: =sum(AK3-AK$358)/AK$359 -> -0.21564587 | AN3: =(AK3 * LOG(AH3 + 1)) / LOG(MAX(AH$2:AH$356) + 1) * 100 -> 7252.7944 | AO3: =sum(AN3-AN$358)/AN$359 -> -0.55702682 | AP3: =PERCENTRANK(AO$2:AO$356,AO3) -> 0.223 | AQ3: 24.73 | AR3: =PERCENTRANK(AQ$2:AQ$356,AQ3) -> 0.969 | AS3: =sum(AQ3-AQ$358)/AQ$359 -> 1.959206 | AT3: 71.94 | AU3: =PERCENTRANK(AT$2:AT$356,AT3) -> 0.302 | AV3: =sum(AT3-AT$358)/AT$359 -> -0.43170026 | AW3: =(AT3 * LOG(AQ3 + 1)) / LOG(MAX(AQ$2:AQ$356) + 1) * 100 -> 6771.4736 | AX3: =sum(AW3-AW$358)/AW$359 -> 0.60325561 | AY3: =PERCENTRANK(AX$2:AX$356,AX3) -> 0.732 | AZ3: 7.83 | BA3: =PERCENTRANK(AZ$2:AZ$356,AZ3) -> 0.839 | BB3: =sum(AZ3-AZ$358)/AZ$359 -> 1.0009943 | BC3: 44.67 | BD3: =PERCENTRANK(BC$2:BC$356,BC3) -> 0.189 | BE3: =sum(BC3-BC$358)/BC$359 -> -0.82313099 | BF3: =(BC3 * LOG(AZ3 + 1)) / LOG(MAX(AZ$2:AZ$356) + 1) * 100 -> 3709.1151 | BG3: =sum(BF3-BF$358)/BF$359 -> 0.042029708 | BH3: =PERCENTRANK(BG$2:BG$356,BG3) -> 0.508 | BI3: 9.03 | BJ3: =PERCENTRANK(BI$2:BI$356,BI3) -> 0.706 | BK3: =sum(BI3-BI$358)/BI$359 -> 0.54224011 | BL3: 58.96 | BM3: =PERCENTRANK(BL$2:BL$356,BL3) -> 0.085 | BN3: =sum(BL3-BL$358)/BL$359 -> -1.4336895 | BO3: =(BL3 * LOG(BI3 + 1)) / LOG(MAX(BI$2:BI$356) + 1) * 100 -> 4950.3869 | BP3: =sum(BO3-BO$358)/BO$359 -> -0.58356624 | BQ3: =PERCENTRANK(BP$2:BP$356,BP3) -> 0.268 | BR3: =sum(AO3,AX3,BG3,BP3) -> -0.49530774 | BS3: =PERCENTRANK(BR$2:BR$356,BR3) -> 0.395
A4: 2022 | B4: B. Washington | C4: Atlanta United II | D4: {=INDEX( TP!C:C, MATCH( 1, (TP!A:A = A4) * (TP!B:B = C4), 0 ) )} -> 49.82 | E4: =sum(AF4,BR4) -> -2.1859037 | F4: =PERCENTRANK(E$2:E$356,E4) -> 0.28 | G4: 8.31 | H4: =PERCENTRANK(G$2:G$356,G4) -> 0.98 | I4: =sum(G4-G$358)/G$359 -> 2.1449253 | J4: =G4 * (2/(1+EXP(-7*(($D4/100)-0.5)))) -> 8.2576477 | K4: =PERCENTRANK(J$2:J$356,J4) -> 0.966 | L4: =sum(J4-J$358)/J$359 -> 2.0545232 | M4: 76.51 | N4: =PERCENTRANK(M$2:M$356,M4) -> 0.975 | O4: =sum(M4-M$358)/M$359 -> 1.8439949 | P4: =(M4 * LOG(J4 + 1)) / LOG(MAX(J$2:J$356) + 1) * 100 -> 7202.988 | Q4: =sum(P4-P$358)/P$359 -> 2.7144252 | R4: =PERCENTRANK(Q$2:Q$356,Q4) -> 1 | S4: 3.23 | T4: =S4 * (2/(1+EXP(-7*(($D4/100)-0.5)))) -> 3.2096513 | U4: =PERCENTRANK(T$2:T$356,T4) -> 0.316 | V4: =sum(S4-S$358)/S$359 -> -0.50495221 | W4: 74.14 | X4: =PERCENTRANK(W$2:W$356,W4) -> 0.972 | Y4: =sum(W4-W$358)/W$359 -> 1.774498 | Z4: =(W4 * LOG(T4 + 1)) / LOG(MAX(T$2:T$356) + 1) * 100 -> 5152.4006 | AA4: =sum(Z4-Z$358)/Z$359 -> 0.69933538 | AB4: =PERCENTRANK(AA$2:AA$356,AA4) -> 0.74 | AC4: 5.28 | AD4: =PERCENTRANK(AC$2:AC$356,AC4) -> 0.175 | AE4: =sum(AC4-AC$358)/AC$359 -> -0.90380493 | AF4: =sum(Q4,AA4,AE4) -> 2.5099556 | AG4: =PERCENTRANK(AF$2:AF$356,AF4) -> 0.895 | AH4: 15.5 | AI4: =PERCENTRANK(AH$2:AH$356,AH4) -> 0.263 | AJ4: =sum(AH4-AH$358)/AH$359 -> -0.57225824 | AK4: 93.53 | AL4: =PERCENTRANK(AK$2:AK$356,AK4) -> 0.311 | AM4: =sum(AK4-AK$358)/AK$359 -> -0.15056127 | AN4: =(AK4 * LOG(AH4 + 1)) / LOG(MAX(AH$2:AH$356) + 1) * 100 -> 7380.6972 | AO4: =sum(AN4-AN$358)/AN$359 -> -0.42086697 | AP4: =PERCENTRANK(AO$2:AO$356,AO4) -> 0.288 | AQ4: 13.83 | AR4: =PERCENTRANK(AQ$2:AQ$356,AQ4) -> 0.088 | AS4: =sum(AQ4-AQ$358)/AQ$359 -> -1.2782349 | AT4: 78.63 | AU4: =PERCENTRANK(AT$2:AT$356,AT4) -> 0.768 | AV4: =sum(AT4-AT$358)/AT$359 -> 0.71082348 | AW4: =(AT4 * LOG(AQ4 + 1)) / LOG(MAX(AQ$2:AQ$356) + 1) * 100 -> 6145.4788 | AX4: =sum(AW4-AW$358)/AW$359 -> -0.28017165 | AY4: =PERCENTRANK(AX$2:AX$356,AX4) -> 0.37 | AZ4: 2.62 | BA4: =PERCENTRANK(AZ$2:AZ$356,AZ4) -> 0.02 | BB4: =sum(AZ4-AZ$358)/AZ$359 -> -1.7457922 | BC4: 38.3 | BD4: =PERCENTRANK(BC$2:BC$356,BC4) -> 0.045 | BE4: =sum(BC4-BC$358)/BC$359 -> -1.6943834 | BF4: =(BC4 * LOG(AZ4 + 1)) / LOG(MAX(AZ$2:AZ$356) + 1) * 100 -> 1878.3018 | BG4: =sum(BF4-BF$358)/BF$359 -> -2.3094791 | BH4: =PERCENTRANK(BG$2:BG$356,BG4) -> 0.023 | BI4: 5.58 | BJ4: =PERCENTRANK(BI$2:BI$356,BI4) -> 0.073 | BK4: =sum(BI4-BI$358)/BI$359 -> -1.3849467 | BL4: 58 | BM4: =PERCENTRANK(BL$2:BL$356,BL4) -> 0.056 | BN4: =sum(BL4-BL$358)/BL$359 -> -1.5794767 | BO4: =(BL4 * LOG(BI4 + 1)) / LOG(MAX(BI$2:BI$356) + 1) * 100 -> 3979.4061 | BP4: =sum(BO4-BO$358)/BO$359 -> -1.6853417 | BQ4: =PERCENTRANK(BP$2:BP$356,BP4) -> 0.048 | BR4: =sum(AO4,AX4,BG4,BP4) -> -4.6958594 | BS4: =PERCENTRANK(BR$2:BR$356,BR4) -> 0.073
A5: 2022 | B5: E. Morales | C5: Atlanta United II | D5: {=INDEX( TP!C:C, MATCH( 1, (TP!A:A = A5) * (TP!B:B = C5), 0 ) )} -> 49.82 | E5: =sum(AF5,BR5) -> -3.8840481 | F5: =PERCENTRANK(E$2:E$356,E5) -> 0.147 | G5: 7.59 | H5: =PERCENTRANK(G$2:G$356,G5) -> 0.938 | I5: =sum(G5-G$358)/G$359 -> 1.6245634 | J5: =G5 * (2/(1+EXP(-7*(($D5/100)-0.5)))) -> 7.5421836 | K5: =PERCENTRANK(J$2:J$356,J5) -> 0.918 | L5: =sum(J5-J$358)/J$359 -> 1.5578816 | M5: 55.07 | N5: =PERCENTRANK(M$2:M$356,M5) -> 0.028 | O5: =sum(M5-M$358)/M$359 -> -1.9036424 | P5: =(M5 * LOG(J5 + 1)) / LOG(MAX(J$2:J$356) + 1) * 100 -> 4997.1501 | Q5: =sum(P5-P$358)/P$359 -> -0.05886329 | R5: =PERCENTRANK(Q$2:Q$356,Q5) -> 0.472 | S5: 4.24 | T5: =S5 * (2/(1+EXP(-7*(($D5/100)-0.5)))) -> 4.2132884 | U5: =PERCENTRANK(T$2:T$356,T5) -> 0.678 | V5: =sum(S5-S$358)/S$359 -> 0.38811055 | W5: 61.04 | X5: =PERCENTRANK(W$2:W$356,W5) -> 0.573 | Y5: =sum(W5-W$358)/W$359 -> 0.27089438 | Z5: =(W5 * LOG(T5 + 1)) / LOG(MAX(T$2:T$356) + 1) * 100 -> 4873.0689 | AA5: =sum(Z5-Z$358)/Z$359 -> 0.44377501 | AB5: =PERCENTRANK(AA$2:AA$356,AA5) -> 0.65 | AC5: 8.22 | AD5: =PERCENTRANK(AC$2:AC$356,AC5) -> 0.915 | AE5: =sum(AC5-AC$358)/AC$359 -> 1.4504458 | AF5: =sum(Q5,AA5,AE5) -> 1.8353576 | AG5: =PERCENTRANK(AF$2:AF$356,AF5) -> 0.845 | AH5: 17 | AI5: =PERCENTRANK(AH$2:AH$356,AH5) -> 0.424 | AJ5: =sum(AH5-AH$358)/AH$359 -> -0.2826291 | AK5: 93.2 | AL5: =PERCENTRANK(AK$2:AK$356,AK5) -> 0.291 | AM5: =sum(AK5-AK$358)/AK$359 -> -0.24818817 | AN5: =(AK5 * LOG(AH5 + 1)) / LOG(MAX(AH$2:AH$356) + 1) * 100 -> 7582.9316 | AO5: =sum(AN5-AN$358)/AN$359 -> -0.20557682 | AP5: =PERCENTRANK(AO$2:AO$356,AO5) -> 0.387 | AQ5: 11.77 | AR5: =PERCENTRANK(AQ$2:AQ$356,AQ5) -> 0.025 | AS5: =sum(AQ5-AQ$358)/AQ$359 -> -1.8900815 | AT5: 69.63 | AU5: =PERCENTRANK(AT$2:AT$356,AT5) -> 0.164 | AV5: =sum(AT5-AT$358)/AT$359 -> -0.82620397 | AW5: =(AT5 * LOG(AQ5 + 1)) / LOG(MAX(AQ$2:AQ$356) + 1) * 100 -> 5140.2552 | AX5: =sum(AW5-AW$358)/AW$359 -> -1.6987807 | AY5: =PERCENTRANK(AX$2:AX$356,AX5) -> 0.056 | AZ5: 4.29 | BA5: =PERCENTRANK(AZ$2:AZ$356,AZ5) -> 0.218 | BB5: =sum(AZ5-AZ$358)/AZ$359 -> -0.86534433 | BC5: 50 | BD5: =PERCENTRANK(BC$2:BC$356,BC5) -> 0.444 | BE5: =sum(BC5-BC$358)/BC$359 -> -0.094123851 | BF5: =(BC5 * LOG(AZ5 + 1)) / LOG(MAX(AZ$2:AZ$356) + 1) * 100 -> 3175.1423 | BG5: =sum(BF5-BF$358)/BF$359 -> -0.64380851 | BH5: =PERCENTRANK(BG$2:BG$356,BG5) -> 0.254 | BI5: 4.95 | BJ5: =PERCENTRANK(BI$2:BI$356,BI5) -> 0.037 | BK5: =sum(BI5-BI$358)/BI$359 -> -1.7368678 | BL5: 41.11 | BM5: =PERCENTRANK(BL$2:BL$356,BL5) -> 0 | BN5: =sum(BL5-BL$358)/BL$359 -> -4.1444201 | BO5: =(BL5 * LOG(BI5 + 1)) / LOG(MAX(BI$2:BI$356) + 1) * 100 -> 2669.9029 | BP5: =sum(BO5-BO$358)/BO$359 -> -3.1712397 | BQ5: =PERCENTRANK(BP$2:BP$356,BP5) -> 0 | BR5: =sum(AO5,AX5,BG5,BP5) -> -5.7194057 | BS5: =PERCENTRANK(BR$2:BR$356,BR5) -> 0.045
A6: 2022 | B6: A. Crognale | C6: Birmingham Legion | D6: {=INDEX( TP!C:C, MATCH( 1, (TP!A:A = A6) * (TP!B:B = C6), 0 ) )} -> 49.76 | E6: =sum(AF6,BR6) -> 4.0468753 | F6: =PERCENTRANK(E$2:E$356,E6) -> 0.859 | G6: 4.68 | H6: =PERCENTRANK(G$2:G$356,G6) -> 0.328 | I6: =sum(G6-G$358)/G$359 -> -0.47856603 | J6: =G6 * (2/(1+EXP(-7*(($D6/100)-0.5)))) -> 4.6406889 | K6: =PERCENTRANK(J$2:J$356,J6) -> 0.351 | L6: =sum(J6-J$358)/J$359 -> -0.4561996 | M6: 65.64 | N6: =PERCENTRANK(M$2:M$356,M6) -> 0.46 | O6: =sum(M6-M$358)/M$359 -> -0.05604321 | P6: =(M6 * LOG(J6 + 1)) / LOG(MAX(J$2:J$356) + 1) * 100 -> 4803.8881 | Q6: =sum(P6-P$358)/P$359 -> -0.30184187 | R6: =PERCENTRANK(Q$2:Q$356,Q6) -> 0.359 | S6: 4.4 | T6: =S6 * (2/(1+EXP(-7*(($D6/100)-0.5)))) -> 4.3630409 | U6: =PERCENTRANK(T$2:T$356,T6) -> 0.712 | V6: =sum(S6-S$358)/S$359 -> 0.52958584 | W6: 68.63 | X6: =PERCENTRANK(W$2:W$356,W6) -> 0.876 | Y6: =sum(W6-W$358)/W$359 -> 1.1420663 | Z6: =(W6 * LOG(T6 + 1)) / LOG(MAX(T$2:T$356) + 1) * 100 -> 5572.981 | AA6: =sum(Z6-Z$358)/Z$359 -> 1.084124 | AB6: =PERCENTRANK(AA$2:AA$356,AA6) -> 0.845 | AC6: 7.34 | AD6: =PERCENTRANK(AC$2:AC$356,AC6) -> 0.791 | AE6: =sum(AC6-AC$358)/AC$359 -> 0.74577215 | AF6: =sum(Q6,AA6,AE6) -> 1.5280543 | AG6: =PERCENTRANK(AF$2:AF$356,AF6) -> 0.797 | AH6: 15.78 | AI6: =PERCENTRANK(AH$2:AH$356,AH6) -> 0.314 | AJ6: =sum(AH6-AH$358)/AH$359 -> -0.51819414 | AK6: 92.17 | AL6: =PERCENTRANK(AK$2:AK$356,AK6) -> 0.192 | AM6: =sum(AK6-AK$358)/AK$359 -> -0.55290243 | AN6: =(AK6 * LOG(AH6 + 1)) / LOG(MAX(AH$2:AH$356) + 1) * 100 -> 7317.0349 | AO6: =sum(AN6-AN$358)/AN$359 -> -0.48863918 | AP6: =PERCENTRANK(AO$2:AO$356,AO6) -> 0.251 | AQ6: 18.36 | AR6: =PERCENTRANK(AQ$2:AQ$356,AQ6) -> 0.528 | AS6: =sum(AQ6-AQ$358)/AQ$359 -> 0.067233687 | AT6: 75.59 | AU6: =PERCENTRANK(AT$2:AT$356,AT6) -> 0.537 | AV6: =sum(AT6-AT$358)/AT$359 -> 0.19164976 | AW6: =(AT6 * LOG(AQ6 + 1)) / LOG(MAX(AQ$2:AQ$356) + 1) * 100 -> 6491.8602 | AX6: =sum(AW6-AW$358)/AW$359 -> 0.20865474 | AY6: =PERCENTRANK(AX$2:AX$356,AX6) -> 0.585 | AZ6: 7.84 | BA6: =PERCENTRANK(AZ$2:AZ$356,AZ6) -> 0.842 | BB6: =sum(AZ6-AZ$358)/AZ$359 -> 1.0062665 | BC6: 58.61 | BD6: =PERCENTRANK(BC$2:BC$356,BC6) -> 0.881 | BE6: =sum(BC6-BC$358)/BC$359 -> 1.0835031 | BF6: =(BC6 * LOG(AZ6 + 1)) / LOG(MAX(AZ$2:AZ$356) + 1) * 100 -> 4869.1337 | BG6: =sum(BF6-BF$358)/BF$359 -> 1.5319653 | BH6: =PERCENTRANK(BG$2:BG$356,BG6) -> 0.949 | BI6: 10.23 | BJ6: =PERCENTRANK(BI$2:BI$356,BI6) -> 0.887 | BK6: =sum(BI6-BI$358)/BI$359 -> 1.2125659 | BL6: 74.72 | BM6: =PERCENTRANK(BL$2:BL$356,BL6) -> 0.836 | BN6: =sum(BL6-BL$358)/BL$359 -> 0.95965018 | BO6: =(BL6 * LOG(BI6 + 1)) / LOG(MAX(BI$2:BI$356) + 1) * 100 -> 6581.1267 | BP6: =sum(BO6-BO$358)/BO$359 -> 1.2668401 | BQ6: =PERCENTRANK(BP$2:BP$356,BP6) -> 0.915 | BR6: =sum(AO6,AX6,BG6,BP6) -> 2.5188209 | BS6: =PERCENTRANK(BR$2:BR$356,BR6) -> 0.794
A7: 2022 | B7: P. Kavita | C7: Birmingham Legion | D7: {=INDEX( TP!C:C, MATCH( 1, (TP!A:A = A7) * (TP!B:B = C7), 0 ) )} -> 49.76 | E7: =sum(AF7,BR7) -> -2.6784533 | F7: =PERCENTRANK(E$2:E$356,E7) -> 0.237 | G7: 5 | H7: =PERCENTRANK(G$2:G$356,G7) -> 0.429 | I7: =sum(G7-G$358)/G$359 -> -0.24729406 | J7: =G7 * (2/(1+EXP(-7*(($D7/100)-0.5)))) -> 4.958001 | K7: =PERCENTRANK(J$2:J$356,J7) -> 0.436 | L7: =sum(J7-J$358)/J$359 -> -0.23593648 | M7: 75.68 | N7: =PERCENTRANK(M$2:M$356,M7) -> 0.958 | O7: =sum(M7-M$358)/M$359 -> 1.6989138 | P7: =(M7 * LOG(J7 + 1)) / LOG(MAX(J$2:J$356) + 1) * 100 -> 5713.8853 | Q7: =sum(P7-P$358)/P$359 -> 0.84225162 | R7: =PERCENTRANK(Q$2:Q$356,Q7) -> 0.814 | S7: 3.67 | T7: =S7 * (2/(1+EXP(-7*(($D7/100)-0.5)))) -> 3.6391727 | U7: =PERCENTRANK(T$2:T$356,T7) -> 0.477 | V7: =sum(S7-S$358)/S$359 -> -0.11589516 | W7: 50.74 | X7: =PERCENTRANK(W$2:W$356,W7) -> 0.181 | Y7: =sum(W7-W$358)/W$359 -> -0.91132834 | Z7: =(W7 * LOG(T7 + 1)) / LOG(MAX(T$2:T$356) + 1) * 100 -> 3764.55 | AA7: =sum(Z7-Z$358)/Z$359 -> -0.57040814 | AB7: =PERCENTRANK(AA$2:AA$356,AA7) -> 0.285 | AC7: 5.51 | AD7: =PERCENTRANK(AC$2:AC$356,AC7) -> 0.246 | AE7: =sum(AC7-AC$358)/AC$359 -> -0.71962884 | AF7: =sum(Q7,AA7,AE7) -> -0.44778537 | AG7: =PERCENTRANK(AF$2:AF$356,AF7) -> 0.41 | AH7: 15.72 | AI7: =PERCENTRANK(AH$2:AH$356,AH7) -> 0.297 | AJ7: =sum(AH7-AH$358)/AH$359 -> -0.5297793 | AK7: 96.74 | AL7: =PERCENTRANK(AK$2:AK$356,AK7) -> 0.819 | AM7: =sum(AK7-AK$358)/AK$359 -> 0.79908223 | AN7: =(AK7 * LOG(AH7 + 1)) / LOG(MAX(AH$2:AH$356) + 1) * 100 -> 7670.0756 | AO7: =sum(AN7-AN$358)/AN$359 -> -0.11280705 | AP7: =PERCENTRANK(AO$2:AO$356,AO7) -> 0.424 | AQ7: 11.4 | AR7: =PERCENTRANK(AQ$2:AQ$356,AQ7) -> 0.023 | AS7: =sum(AQ7-AQ$358)/AQ$359 -> -1.9999763 | AT7: 80.81 | AU7: =PERCENTRANK(AT$2:AT$356,AT7) -> 0.867 | AV7: =sum(AT7-AT$358)/AT$359 -> 1.0831257 | AW7: =(AT7 * LOG(AQ7 + 1)) / LOG(MAX(AQ$2:AQ$356) + 1) * 100 -> 5896.7267 | AX7: =sum(AW7-AW$358)/AW$359 -> -0.63121994 | AY7: =PERCENTRANK(AX$2:AX$356,AX7) -> 0.249 | AZ7: 3.13 | BA7: =PERCENTRANK(AZ$2:AZ$356,AZ7) -> 0.054 | BB7: =sum(AZ7-AZ$358)/AZ$359 -> -1.4769129 | BC7: 63.79 | BD7: =PERCENTRANK(BC$2:BC$356,BC7) -> 0.98 | BE7: =sum(BC7-BC$358)/BC$359 -> 1.7919941 | BF7: =(BC7 * LOG(AZ7 + 1)) / LOG(MAX(AZ$2:AZ$356) + 1) * 100 -> 3448.8901 | BG7: =sum(BF7-BF$358)/BF$359 -> -0.29220496 | BH7: =PERCENTRANK(BG$2:BG$356,BG7) -> 0.381 | BI7: 4.62 | BJ7: =PERCENTRANK(BI$2:BI$356,BI7) -> 0.023 | BK7: =sum(BI7-BI$358)/BI$359 -> -1.9212074 | BL7: 70.18 | BM7: =PERCENTRANK(BL$2:BL$356,BL7) -> 0.607 | BN7: =sum(BL7-BL$358)/BL$359 -> 0.27019825 | BO7: =(BL7 * LOG(BI7 + 1)) / LOG(MAX(BI$2:BI$356) + 1) * 100 -> 4412.0351 | BP7: =sum(BO7-BO$358)/BO$359 -> -1.194436 | BQ7: =PERCENTRANK(BP$2:BP$356,BP7) -> 0.116 | BR7: =sum(AO7,AX7,BG7,BP7) -> -2.2306679 | BS7: =PERCENTRANK(BR$2:BR$356,BR7) -> 0.206
